[2023-03-06T12:16:23.260+0000] {processor.py:153} INFO - Started process (PID=590) to work on /opt/airflow/dags/s3_to_snowflake.py
[2023-03-06T12:16:23.260+0000] {processor.py:743} INFO - Processing file /opt/airflow/dags/s3_to_snowflake.py for tasks to queue
[2023-03-06T12:16:23.261+0000] {logging_mixin.py:137} INFO - [2023-03-06T12:16:23.261+0000] {dagbag.py:538} INFO - Filling up the DagBag from /opt/airflow/dags/s3_to_snowflake.py
[2023-03-06T12:16:23.281+0000] {logging_mixin.py:137} INFO - [2023-03-06T12:16:23.281+0000] {dagbag.py:343} ERROR - Failed to import: /opt/airflow/dags/s3_to_snowflake.py
Traceback (most recent call last):
  File "/home/airflow/.local/lib/python3.7/site-packages/airflow/models/dagbag.py", line 339, in parse
    loader.exec_module(new_module)
  File "<frozen importlib._bootstrap_external>", line 728, in exec_module
  File "<frozen importlib._bootstrap>", line 219, in _call_with_frames_removed
  File "/opt/airflow/dags/s3_to_snowflake.py", line 6, in <module>
    from airflow.providers.snowflake.operators.snowflake import SnowflakeOperator
ModuleNotFoundError: No module named 'airflow.providers.snowflake'
[2023-03-06T12:16:23.282+0000] {processor.py:755} WARNING - No viable dags retrieved from /opt/airflow/dags/s3_to_snowflake.py
[2023-03-06T12:16:23.296+0000] {processor.py:175} INFO - Processing /opt/airflow/dags/s3_to_snowflake.py took 0.038 seconds
[2023-03-06T12:16:53.412+0000] {processor.py:153} INFO - Started process (PID=632) to work on /opt/airflow/dags/s3_to_snowflake.py
[2023-03-06T12:16:53.412+0000] {processor.py:743} INFO - Processing file /opt/airflow/dags/s3_to_snowflake.py for tasks to queue
[2023-03-06T12:16:53.413+0000] {logging_mixin.py:137} INFO - [2023-03-06T12:16:53.413+0000] {dagbag.py:538} INFO - Filling up the DagBag from /opt/airflow/dags/s3_to_snowflake.py
[2023-03-06T12:16:53.423+0000] {logging_mixin.py:137} INFO - [2023-03-06T12:16:53.422+0000] {dagbag.py:343} ERROR - Failed to import: /opt/airflow/dags/s3_to_snowflake.py
Traceback (most recent call last):
  File "/home/airflow/.local/lib/python3.7/site-packages/airflow/models/dagbag.py", line 339, in parse
    loader.exec_module(new_module)
  File "<frozen importlib._bootstrap_external>", line 728, in exec_module
  File "<frozen importlib._bootstrap>", line 219, in _call_with_frames_removed
  File "/opt/airflow/dags/s3_to_snowflake.py", line 6, in <module>
    from airflow.providers.snowflake.operators.snowflake import SnowflakeOperator
ModuleNotFoundError: No module named 'airflow.providers.snowflake'
[2023-03-06T12:16:53.423+0000] {processor.py:755} WARNING - No viable dags retrieved from /opt/airflow/dags/s3_to_snowflake.py
[2023-03-06T12:16:53.436+0000] {processor.py:175} INFO - Processing /opt/airflow/dags/s3_to_snowflake.py took 0.026 seconds
[2023-03-06T12:17:23.570+0000] {processor.py:153} INFO - Started process (PID=695) to work on /opt/airflow/dags/s3_to_snowflake.py
[2023-03-06T12:17:23.578+0000] {processor.py:743} INFO - Processing file /opt/airflow/dags/s3_to_snowflake.py for tasks to queue
[2023-03-06T12:17:23.579+0000] {logging_mixin.py:137} INFO - [2023-03-06T12:17:23.579+0000] {dagbag.py:538} INFO - Filling up the DagBag from /opt/airflow/dags/s3_to_snowflake.py
[2023-03-06T12:17:23.589+0000] {logging_mixin.py:137} INFO - [2023-03-06T12:17:23.589+0000] {dagbag.py:343} ERROR - Failed to import: /opt/airflow/dags/s3_to_snowflake.py
Traceback (most recent call last):
  File "/home/airflow/.local/lib/python3.7/site-packages/airflow/models/dagbag.py", line 339, in parse
    loader.exec_module(new_module)
  File "<frozen importlib._bootstrap_external>", line 728, in exec_module
  File "<frozen importlib._bootstrap>", line 219, in _call_with_frames_removed
  File "/opt/airflow/dags/s3_to_snowflake.py", line 6, in <module>
    from airflow.providers.snowflake.operators.snowflake import SnowflakeOperator
ModuleNotFoundError: No module named 'airflow.providers.snowflake'
[2023-03-06T12:17:23.589+0000] {processor.py:755} WARNING - No viable dags retrieved from /opt/airflow/dags/s3_to_snowflake.py
[2023-03-06T12:17:23.602+0000] {processor.py:175} INFO - Processing /opt/airflow/dags/s3_to_snowflake.py took 0.034 seconds
[2023-03-06T12:17:53.716+0000] {processor.py:153} INFO - Started process (PID=737) to work on /opt/airflow/dags/s3_to_snowflake.py
[2023-03-06T12:17:53.716+0000] {processor.py:743} INFO - Processing file /opt/airflow/dags/s3_to_snowflake.py for tasks to queue
[2023-03-06T12:17:53.717+0000] {logging_mixin.py:137} INFO - [2023-03-06T12:17:53.716+0000] {dagbag.py:538} INFO - Filling up the DagBag from /opt/airflow/dags/s3_to_snowflake.py
[2023-03-06T12:17:53.726+0000] {logging_mixin.py:137} INFO - [2023-03-06T12:17:53.726+0000] {dagbag.py:343} ERROR - Failed to import: /opt/airflow/dags/s3_to_snowflake.py
Traceback (most recent call last):
  File "/home/airflow/.local/lib/python3.7/site-packages/airflow/models/dagbag.py", line 339, in parse
    loader.exec_module(new_module)
  File "<frozen importlib._bootstrap_external>", line 728, in exec_module
  File "<frozen importlib._bootstrap>", line 219, in _call_with_frames_removed
  File "/opt/airflow/dags/s3_to_snowflake.py", line 6, in <module>
    from airflow.providers.snowflake.operators.snowflake import SnowflakeOperator
ModuleNotFoundError: No module named 'airflow.providers.snowflake'
[2023-03-06T12:17:53.726+0000] {processor.py:755} WARNING - No viable dags retrieved from /opt/airflow/dags/s3_to_snowflake.py
[2023-03-06T12:17:53.738+0000] {processor.py:175} INFO - Processing /opt/airflow/dags/s3_to_snowflake.py took 0.024 seconds
[2023-03-06T12:18:23.853+0000] {processor.py:153} INFO - Started process (PID=799) to work on /opt/airflow/dags/s3_to_snowflake.py
[2023-03-06T12:18:23.860+0000] {processor.py:743} INFO - Processing file /opt/airflow/dags/s3_to_snowflake.py for tasks to queue
[2023-03-06T12:18:23.861+0000] {logging_mixin.py:137} INFO - [2023-03-06T12:18:23.861+0000] {dagbag.py:538} INFO - Filling up the DagBag from /opt/airflow/dags/s3_to_snowflake.py
[2023-03-06T12:18:23.871+0000] {logging_mixin.py:137} INFO - [2023-03-06T12:18:23.870+0000] {dagbag.py:343} ERROR - Failed to import: /opt/airflow/dags/s3_to_snowflake.py
Traceback (most recent call last):
  File "/home/airflow/.local/lib/python3.7/site-packages/airflow/models/dagbag.py", line 339, in parse
    loader.exec_module(new_module)
  File "<frozen importlib._bootstrap_external>", line 728, in exec_module
  File "<frozen importlib._bootstrap>", line 219, in _call_with_frames_removed
  File "/opt/airflow/dags/s3_to_snowflake.py", line 6, in <module>
    from airflow.providers.snowflake.operators.snowflake import SnowflakeOperator
ModuleNotFoundError: No module named 'airflow.providers.snowflake'
[2023-03-06T12:18:23.871+0000] {processor.py:755} WARNING - No viable dags retrieved from /opt/airflow/dags/s3_to_snowflake.py
[2023-03-06T12:18:23.883+0000] {processor.py:175} INFO - Processing /opt/airflow/dags/s3_to_snowflake.py took 0.032 seconds
[2023-03-06T12:18:54.001+0000] {processor.py:153} INFO - Started process (PID=841) to work on /opt/airflow/dags/s3_to_snowflake.py
[2023-03-06T12:18:54.001+0000] {processor.py:743} INFO - Processing file /opt/airflow/dags/s3_to_snowflake.py for tasks to queue
[2023-03-06T12:18:54.001+0000] {logging_mixin.py:137} INFO - [2023-03-06T12:18:54.001+0000] {dagbag.py:538} INFO - Filling up the DagBag from /opt/airflow/dags/s3_to_snowflake.py
[2023-03-06T12:18:54.011+0000] {logging_mixin.py:137} INFO - [2023-03-06T12:18:54.010+0000] {dagbag.py:343} ERROR - Failed to import: /opt/airflow/dags/s3_to_snowflake.py
Traceback (most recent call last):
  File "/home/airflow/.local/lib/python3.7/site-packages/airflow/models/dagbag.py", line 339, in parse
    loader.exec_module(new_module)
  File "<frozen importlib._bootstrap_external>", line 728, in exec_module
  File "<frozen importlib._bootstrap>", line 219, in _call_with_frames_removed
  File "/opt/airflow/dags/s3_to_snowflake.py", line 6, in <module>
    from airflow.providers.snowflake.operators.snowflake import SnowflakeOperator
ModuleNotFoundError: No module named 'airflow.providers.snowflake'
[2023-03-06T12:18:54.011+0000] {processor.py:755} WARNING - No viable dags retrieved from /opt/airflow/dags/s3_to_snowflake.py
[2023-03-06T12:18:54.024+0000] {processor.py:175} INFO - Processing /opt/airflow/dags/s3_to_snowflake.py took 0.025 seconds
[2023-03-06T12:19:24.134+0000] {processor.py:153} INFO - Started process (PID=903) to work on /opt/airflow/dags/s3_to_snowflake.py
[2023-03-06T12:19:24.134+0000] {processor.py:743} INFO - Processing file /opt/airflow/dags/s3_to_snowflake.py for tasks to queue
[2023-03-06T12:19:24.135+0000] {logging_mixin.py:137} INFO - [2023-03-06T12:19:24.135+0000] {dagbag.py:538} INFO - Filling up the DagBag from /opt/airflow/dags/s3_to_snowflake.py
[2023-03-06T12:19:24.146+0000] {logging_mixin.py:137} INFO - [2023-03-06T12:19:24.146+0000] {dagbag.py:343} ERROR - Failed to import: /opt/airflow/dags/s3_to_snowflake.py
Traceback (most recent call last):
  File "/home/airflow/.local/lib/python3.7/site-packages/airflow/models/dagbag.py", line 339, in parse
    loader.exec_module(new_module)
  File "<frozen importlib._bootstrap_external>", line 728, in exec_module
  File "<frozen importlib._bootstrap>", line 219, in _call_with_frames_removed
  File "/opt/airflow/dags/s3_to_snowflake.py", line 6, in <module>
    from airflow.providers.snowflake.operators.snowflake import SnowflakeOperator
ModuleNotFoundError: No module named 'airflow.providers.snowflake'
[2023-03-06T12:19:24.146+0000] {processor.py:755} WARNING - No viable dags retrieved from /opt/airflow/dags/s3_to_snowflake.py
[2023-03-06T12:19:24.158+0000] {processor.py:175} INFO - Processing /opt/airflow/dags/s3_to_snowflake.py took 0.025 seconds
[2023-03-06T12:19:54.273+0000] {processor.py:153} INFO - Started process (PID=945) to work on /opt/airflow/dags/s3_to_snowflake.py
[2023-03-06T12:19:54.274+0000] {processor.py:743} INFO - Processing file /opt/airflow/dags/s3_to_snowflake.py for tasks to queue
[2023-03-06T12:19:54.274+0000] {logging_mixin.py:137} INFO - [2023-03-06T12:19:54.274+0000] {dagbag.py:538} INFO - Filling up the DagBag from /opt/airflow/dags/s3_to_snowflake.py
[2023-03-06T12:19:54.283+0000] {logging_mixin.py:137} INFO - [2023-03-06T12:19:54.283+0000] {dagbag.py:343} ERROR - Failed to import: /opt/airflow/dags/s3_to_snowflake.py
Traceback (most recent call last):
  File "/home/airflow/.local/lib/python3.7/site-packages/airflow/models/dagbag.py", line 339, in parse
    loader.exec_module(new_module)
  File "<frozen importlib._bootstrap_external>", line 728, in exec_module
  File "<frozen importlib._bootstrap>", line 219, in _call_with_frames_removed
  File "/opt/airflow/dags/s3_to_snowflake.py", line 6, in <module>
    from airflow.providers.snowflake.operators.snowflake import SnowflakeOperator
ModuleNotFoundError: No module named 'airflow.providers.snowflake'
[2023-03-06T12:19:54.283+0000] {processor.py:755} WARNING - No viable dags retrieved from /opt/airflow/dags/s3_to_snowflake.py
[2023-03-06T12:19:54.296+0000] {processor.py:175} INFO - Processing /opt/airflow/dags/s3_to_snowflake.py took 0.024 seconds
[2023-03-06T12:20:24.413+0000] {processor.py:153} INFO - Started process (PID=1007) to work on /opt/airflow/dags/s3_to_snowflake.py
[2023-03-06T12:20:24.415+0000] {processor.py:743} INFO - Processing file /opt/airflow/dags/s3_to_snowflake.py for tasks to queue
[2023-03-06T12:20:24.415+0000] {logging_mixin.py:137} INFO - [2023-03-06T12:20:24.415+0000] {dagbag.py:538} INFO - Filling up the DagBag from /opt/airflow/dags/s3_to_snowflake.py
[2023-03-06T12:20:24.427+0000] {logging_mixin.py:137} INFO - [2023-03-06T12:20:24.426+0000] {dagbag.py:343} ERROR - Failed to import: /opt/airflow/dags/s3_to_snowflake.py
Traceback (most recent call last):
  File "/home/airflow/.local/lib/python3.7/site-packages/airflow/models/dagbag.py", line 339, in parse
    loader.exec_module(new_module)
  File "<frozen importlib._bootstrap_external>", line 728, in exec_module
  File "<frozen importlib._bootstrap>", line 219, in _call_with_frames_removed
  File "/opt/airflow/dags/s3_to_snowflake.py", line 6, in <module>
    from airflow.providers.snowflake.operators.snowflake import SnowflakeOperator
ModuleNotFoundError: No module named 'airflow.providers.snowflake'
[2023-03-06T12:20:24.427+0000] {processor.py:755} WARNING - No viable dags retrieved from /opt/airflow/dags/s3_to_snowflake.py
[2023-03-06T12:20:24.438+0000] {processor.py:175} INFO - Processing /opt/airflow/dags/s3_to_snowflake.py took 0.027 seconds
[2023-03-06T12:20:54.551+0000] {processor.py:153} INFO - Started process (PID=1059) to work on /opt/airflow/dags/s3_to_snowflake.py
[2023-03-06T12:20:54.551+0000] {processor.py:743} INFO - Processing file /opt/airflow/dags/s3_to_snowflake.py for tasks to queue
[2023-03-06T12:20:54.552+0000] {logging_mixin.py:137} INFO - [2023-03-06T12:20:54.552+0000] {dagbag.py:538} INFO - Filling up the DagBag from /opt/airflow/dags/s3_to_snowflake.py
[2023-03-06T12:20:54.561+0000] {logging_mixin.py:137} INFO - [2023-03-06T12:20:54.560+0000] {dagbag.py:343} ERROR - Failed to import: /opt/airflow/dags/s3_to_snowflake.py
Traceback (most recent call last):
  File "/home/airflow/.local/lib/python3.7/site-packages/airflow/models/dagbag.py", line 339, in parse
    loader.exec_module(new_module)
  File "<frozen importlib._bootstrap_external>", line 728, in exec_module
  File "<frozen importlib._bootstrap>", line 219, in _call_with_frames_removed
  File "/opt/airflow/dags/s3_to_snowflake.py", line 6, in <module>
    from airflow.providers.snowflake.operators.snowflake import SnowflakeOperator
ModuleNotFoundError: No module named 'airflow.providers.snowflake'
[2023-03-06T12:20:54.561+0000] {processor.py:755} WARNING - No viable dags retrieved from /opt/airflow/dags/s3_to_snowflake.py
[2023-03-06T12:20:54.573+0000] {processor.py:175} INFO - Processing /opt/airflow/dags/s3_to_snowflake.py took 0.023 seconds
[2023-03-06T12:21:24.690+0000] {processor.py:153} INFO - Started process (PID=1112) to work on /opt/airflow/dags/s3_to_snowflake.py
[2023-03-06T12:21:24.691+0000] {processor.py:743} INFO - Processing file /opt/airflow/dags/s3_to_snowflake.py for tasks to queue
[2023-03-06T12:21:24.691+0000] {logging_mixin.py:137} INFO - [2023-03-06T12:21:24.691+0000] {dagbag.py:538} INFO - Filling up the DagBag from /opt/airflow/dags/s3_to_snowflake.py
[2023-03-06T12:21:24.703+0000] {logging_mixin.py:137} INFO - [2023-03-06T12:21:24.703+0000] {dagbag.py:343} ERROR - Failed to import: /opt/airflow/dags/s3_to_snowflake.py
Traceback (most recent call last):
  File "/home/airflow/.local/lib/python3.7/site-packages/airflow/models/dagbag.py", line 339, in parse
    loader.exec_module(new_module)
  File "<frozen importlib._bootstrap_external>", line 728, in exec_module
  File "<frozen importlib._bootstrap>", line 219, in _call_with_frames_removed
  File "/opt/airflow/dags/s3_to_snowflake.py", line 6, in <module>
    from airflow.providers.snowflake.operators.snowflake import SnowflakeOperator
ModuleNotFoundError: No module named 'airflow.providers.snowflake'
[2023-03-06T12:21:24.703+0000] {processor.py:755} WARNING - No viable dags retrieved from /opt/airflow/dags/s3_to_snowflake.py
[2023-03-06T12:21:24.715+0000] {processor.py:175} INFO - Processing /opt/airflow/dags/s3_to_snowflake.py took 0.027 seconds
[2023-03-06T12:21:54.826+0000] {processor.py:153} INFO - Started process (PID=1174) to work on /opt/airflow/dags/s3_to_snowflake.py
[2023-03-06T12:21:54.827+0000] {processor.py:743} INFO - Processing file /opt/airflow/dags/s3_to_snowflake.py for tasks to queue
[2023-03-06T12:21:54.827+0000] {logging_mixin.py:137} INFO - [2023-03-06T12:21:54.827+0000] {dagbag.py:538} INFO - Filling up the DagBag from /opt/airflow/dags/s3_to_snowflake.py
[2023-03-06T12:21:54.839+0000] {logging_mixin.py:137} INFO - [2023-03-06T12:21:54.838+0000] {dagbag.py:343} ERROR - Failed to import: /opt/airflow/dags/s3_to_snowflake.py
Traceback (most recent call last):
  File "/home/airflow/.local/lib/python3.7/site-packages/airflow/models/dagbag.py", line 339, in parse
    loader.exec_module(new_module)
  File "<frozen importlib._bootstrap_external>", line 728, in exec_module
  File "<frozen importlib._bootstrap>", line 219, in _call_with_frames_removed
  File "/opt/airflow/dags/s3_to_snowflake.py", line 6, in <module>
    from airflow.providers.snowflake.operators.snowflake import SnowflakeOperator
ModuleNotFoundError: No module named 'airflow.providers.snowflake'
[2023-03-06T12:21:54.839+0000] {processor.py:755} WARNING - No viable dags retrieved from /opt/airflow/dags/s3_to_snowflake.py
[2023-03-06T12:21:54.854+0000] {processor.py:175} INFO - Processing /opt/airflow/dags/s3_to_snowflake.py took 0.030 seconds
[2023-03-06T12:22:24.961+0000] {processor.py:153} INFO - Started process (PID=1216) to work on /opt/airflow/dags/s3_to_snowflake.py
[2023-03-06T12:22:24.963+0000] {processor.py:743} INFO - Processing file /opt/airflow/dags/s3_to_snowflake.py for tasks to queue
[2023-03-06T12:22:24.964+0000] {logging_mixin.py:137} INFO - [2023-03-06T12:22:24.964+0000] {dagbag.py:538} INFO - Filling up the DagBag from /opt/airflow/dags/s3_to_snowflake.py
[2023-03-06T12:22:24.973+0000] {logging_mixin.py:137} INFO - [2023-03-06T12:22:24.973+0000] {dagbag.py:343} ERROR - Failed to import: /opt/airflow/dags/s3_to_snowflake.py
Traceback (most recent call last):
  File "/home/airflow/.local/lib/python3.7/site-packages/airflow/models/dagbag.py", line 339, in parse
    loader.exec_module(new_module)
  File "<frozen importlib._bootstrap_external>", line 728, in exec_module
  File "<frozen importlib._bootstrap>", line 219, in _call_with_frames_removed
  File "/opt/airflow/dags/s3_to_snowflake.py", line 6, in <module>
    from airflow.providers.snowflake.operators.snowflake import SnowflakeOperator
ModuleNotFoundError: No module named 'airflow.providers.snowflake'
[2023-03-06T12:22:24.974+0000] {processor.py:755} WARNING - No viable dags retrieved from /opt/airflow/dags/s3_to_snowflake.py
[2023-03-06T12:22:24.987+0000] {processor.py:175} INFO - Processing /opt/airflow/dags/s3_to_snowflake.py took 0.028 seconds
[2023-03-06T12:22:55.096+0000] {processor.py:153} INFO - Started process (PID=1278) to work on /opt/airflow/dags/s3_to_snowflake.py
[2023-03-06T12:22:55.096+0000] {processor.py:743} INFO - Processing file /opt/airflow/dags/s3_to_snowflake.py for tasks to queue
[2023-03-06T12:22:55.096+0000] {logging_mixin.py:137} INFO - [2023-03-06T12:22:55.096+0000] {dagbag.py:538} INFO - Filling up the DagBag from /opt/airflow/dags/s3_to_snowflake.py
[2023-03-06T12:22:55.107+0000] {logging_mixin.py:137} INFO - [2023-03-06T12:22:55.106+0000] {dagbag.py:343} ERROR - Failed to import: /opt/airflow/dags/s3_to_snowflake.py
Traceback (most recent call last):
  File "/home/airflow/.local/lib/python3.7/site-packages/airflow/models/dagbag.py", line 339, in parse
    loader.exec_module(new_module)
  File "<frozen importlib._bootstrap_external>", line 728, in exec_module
  File "<frozen importlib._bootstrap>", line 219, in _call_with_frames_removed
  File "/opt/airflow/dags/s3_to_snowflake.py", line 6, in <module>
    from airflow.providers.snowflake.operators.snowflake import SnowflakeOperator
ModuleNotFoundError: No module named 'airflow.providers.snowflake'
[2023-03-06T12:22:55.107+0000] {processor.py:755} WARNING - No viable dags retrieved from /opt/airflow/dags/s3_to_snowflake.py
[2023-03-06T12:22:55.119+0000] {processor.py:175} INFO - Processing /opt/airflow/dags/s3_to_snowflake.py took 0.026 seconds
[2023-03-06T12:23:25.228+0000] {processor.py:153} INFO - Started process (PID=1320) to work on /opt/airflow/dags/s3_to_snowflake.py
[2023-03-06T12:23:25.230+0000] {processor.py:743} INFO - Processing file /opt/airflow/dags/s3_to_snowflake.py for tasks to queue
[2023-03-06T12:23:25.230+0000] {logging_mixin.py:137} INFO - [2023-03-06T12:23:25.230+0000] {dagbag.py:538} INFO - Filling up the DagBag from /opt/airflow/dags/s3_to_snowflake.py
[2023-03-06T12:23:25.240+0000] {logging_mixin.py:137} INFO - [2023-03-06T12:23:25.239+0000] {dagbag.py:343} ERROR - Failed to import: /opt/airflow/dags/s3_to_snowflake.py
Traceback (most recent call last):
  File "/home/airflow/.local/lib/python3.7/site-packages/airflow/models/dagbag.py", line 339, in parse
    loader.exec_module(new_module)
  File "<frozen importlib._bootstrap_external>", line 728, in exec_module
  File "<frozen importlib._bootstrap>", line 219, in _call_with_frames_removed
  File "/opt/airflow/dags/s3_to_snowflake.py", line 6, in <module>
    from airflow.providers.snowflake.operators.snowflake import SnowflakeOperator
ModuleNotFoundError: No module named 'airflow.providers.snowflake'
[2023-03-06T12:23:25.240+0000] {processor.py:755} WARNING - No viable dags retrieved from /opt/airflow/dags/s3_to_snowflake.py
[2023-03-06T12:23:25.252+0000] {processor.py:175} INFO - Processing /opt/airflow/dags/s3_to_snowflake.py took 0.026 seconds
[2023-03-06T12:23:55.371+0000] {processor.py:153} INFO - Started process (PID=1382) to work on /opt/airflow/dags/s3_to_snowflake.py
[2023-03-06T12:23:55.371+0000] {processor.py:743} INFO - Processing file /opt/airflow/dags/s3_to_snowflake.py for tasks to queue
[2023-03-06T12:23:55.371+0000] {logging_mixin.py:137} INFO - [2023-03-06T12:23:55.371+0000] {dagbag.py:538} INFO - Filling up the DagBag from /opt/airflow/dags/s3_to_snowflake.py
[2023-03-06T12:23:55.383+0000] {logging_mixin.py:137} INFO - [2023-03-06T12:23:55.382+0000] {dagbag.py:343} ERROR - Failed to import: /opt/airflow/dags/s3_to_snowflake.py
Traceback (most recent call last):
  File "/home/airflow/.local/lib/python3.7/site-packages/airflow/models/dagbag.py", line 339, in parse
    loader.exec_module(new_module)
  File "<frozen importlib._bootstrap_external>", line 728, in exec_module
  File "<frozen importlib._bootstrap>", line 219, in _call_with_frames_removed
  File "/opt/airflow/dags/s3_to_snowflake.py", line 6, in <module>
    from airflow.providers.snowflake.operators.snowflake import SnowflakeOperator
ModuleNotFoundError: No module named 'airflow.providers.snowflake'
[2023-03-06T12:23:55.383+0000] {processor.py:755} WARNING - No viable dags retrieved from /opt/airflow/dags/s3_to_snowflake.py
[2023-03-06T12:23:55.396+0000] {processor.py:175} INFO - Processing /opt/airflow/dags/s3_to_snowflake.py took 0.027 seconds
[2023-03-06T12:24:25.502+0000] {processor.py:153} INFO - Started process (PID=1424) to work on /opt/airflow/dags/s3_to_snowflake.py
[2023-03-06T12:24:25.502+0000] {processor.py:743} INFO - Processing file /opt/airflow/dags/s3_to_snowflake.py for tasks to queue
[2023-03-06T12:24:25.503+0000] {logging_mixin.py:137} INFO - [2023-03-06T12:24:25.503+0000] {dagbag.py:538} INFO - Filling up the DagBag from /opt/airflow/dags/s3_to_snowflake.py
[2023-03-06T12:24:25.515+0000] {logging_mixin.py:137} INFO - [2023-03-06T12:24:25.514+0000] {dagbag.py:343} ERROR - Failed to import: /opt/airflow/dags/s3_to_snowflake.py
Traceback (most recent call last):
  File "/home/airflow/.local/lib/python3.7/site-packages/airflow/models/dagbag.py", line 339, in parse
    loader.exec_module(new_module)
  File "<frozen importlib._bootstrap_external>", line 728, in exec_module
  File "<frozen importlib._bootstrap>", line 219, in _call_with_frames_removed
  File "/opt/airflow/dags/s3_to_snowflake.py", line 6, in <module>
    from airflow.providers.snowflake.operators.snowflake import SnowflakeOperator
ModuleNotFoundError: No module named 'airflow.providers.snowflake'
[2023-03-06T12:24:25.515+0000] {processor.py:755} WARNING - No viable dags retrieved from /opt/airflow/dags/s3_to_snowflake.py
[2023-03-06T12:24:25.529+0000] {processor.py:175} INFO - Processing /opt/airflow/dags/s3_to_snowflake.py took 0.029 seconds
[2023-03-06T12:24:55.634+0000] {processor.py:153} INFO - Started process (PID=1486) to work on /opt/airflow/dags/s3_to_snowflake.py
[2023-03-06T12:24:55.634+0000] {processor.py:743} INFO - Processing file /opt/airflow/dags/s3_to_snowflake.py for tasks to queue
[2023-03-06T12:24:55.634+0000] {logging_mixin.py:137} INFO - [2023-03-06T12:24:55.634+0000] {dagbag.py:538} INFO - Filling up the DagBag from /opt/airflow/dags/s3_to_snowflake.py
[2023-03-06T12:24:55.645+0000] {logging_mixin.py:137} INFO - [2023-03-06T12:24:55.644+0000] {dagbag.py:343} ERROR - Failed to import: /opt/airflow/dags/s3_to_snowflake.py
Traceback (most recent call last):
  File "/home/airflow/.local/lib/python3.7/site-packages/airflow/models/dagbag.py", line 339, in parse
    loader.exec_module(new_module)
  File "<frozen importlib._bootstrap_external>", line 728, in exec_module
  File "<frozen importlib._bootstrap>", line 219, in _call_with_frames_removed
  File "/opt/airflow/dags/s3_to_snowflake.py", line 6, in <module>
    from airflow.providers.snowflake.operators.snowflake import SnowflakeOperator
ModuleNotFoundError: No module named 'airflow.providers.snowflake'
[2023-03-06T12:24:55.645+0000] {processor.py:755} WARNING - No viable dags retrieved from /opt/airflow/dags/s3_to_snowflake.py
[2023-03-06T12:24:55.657+0000] {processor.py:175} INFO - Processing /opt/airflow/dags/s3_to_snowflake.py took 0.025 seconds
[2023-03-06T12:25:25.757+0000] {processor.py:153} INFO - Started process (PID=1528) to work on /opt/airflow/dags/s3_to_snowflake.py
[2023-03-06T12:25:25.757+0000] {processor.py:743} INFO - Processing file /opt/airflow/dags/s3_to_snowflake.py for tasks to queue
[2023-03-06T12:25:25.758+0000] {logging_mixin.py:137} INFO - [2023-03-06T12:25:25.758+0000] {dagbag.py:538} INFO - Filling up the DagBag from /opt/airflow/dags/s3_to_snowflake.py
[2023-03-06T12:25:25.768+0000] {logging_mixin.py:137} INFO - [2023-03-06T12:25:25.768+0000] {dagbag.py:343} ERROR - Failed to import: /opt/airflow/dags/s3_to_snowflake.py
Traceback (most recent call last):
  File "/home/airflow/.local/lib/python3.7/site-packages/airflow/models/dagbag.py", line 339, in parse
    loader.exec_module(new_module)
  File "<frozen importlib._bootstrap_external>", line 728, in exec_module
  File "<frozen importlib._bootstrap>", line 219, in _call_with_frames_removed
  File "/opt/airflow/dags/s3_to_snowflake.py", line 6, in <module>
    from airflow.providers.snowflake.operators.snowflake import SnowflakeOperator
ModuleNotFoundError: No module named 'airflow.providers.snowflake'
[2023-03-06T12:25:25.768+0000] {processor.py:755} WARNING - No viable dags retrieved from /opt/airflow/dags/s3_to_snowflake.py
[2023-03-06T12:25:25.829+0000] {processor.py:175} INFO - Processing /opt/airflow/dags/s3_to_snowflake.py took 0.074 seconds
[2023-03-06T12:25:55.936+0000] {processor.py:153} INFO - Started process (PID=1592) to work on /opt/airflow/dags/s3_to_snowflake.py
[2023-03-06T12:25:55.937+0000] {processor.py:743} INFO - Processing file /opt/airflow/dags/s3_to_snowflake.py for tasks to queue
[2023-03-06T12:25:55.937+0000] {logging_mixin.py:137} INFO - [2023-03-06T12:25:55.937+0000] {dagbag.py:538} INFO - Filling up the DagBag from /opt/airflow/dags/s3_to_snowflake.py
[2023-03-06T12:25:55.947+0000] {logging_mixin.py:137} INFO - [2023-03-06T12:25:55.946+0000] {dagbag.py:343} ERROR - Failed to import: /opt/airflow/dags/s3_to_snowflake.py
Traceback (most recent call last):
  File "/home/airflow/.local/lib/python3.7/site-packages/airflow/models/dagbag.py", line 339, in parse
    loader.exec_module(new_module)
  File "<frozen importlib._bootstrap_external>", line 728, in exec_module
  File "<frozen importlib._bootstrap>", line 219, in _call_with_frames_removed
  File "/opt/airflow/dags/s3_to_snowflake.py", line 6, in <module>
    from airflow.providers.snowflake.operators.snowflake import SnowflakeOperator
ModuleNotFoundError: No module named 'airflow.providers.snowflake'
[2023-03-06T12:25:55.947+0000] {processor.py:755} WARNING - No viable dags retrieved from /opt/airflow/dags/s3_to_snowflake.py
[2023-03-06T12:25:55.960+0000] {processor.py:175} INFO - Processing /opt/airflow/dags/s3_to_snowflake.py took 0.025 seconds
[2023-03-06T12:26:26.073+0000] {processor.py:153} INFO - Started process (PID=1654) to work on /opt/airflow/dags/s3_to_snowflake.py
[2023-03-06T12:26:26.073+0000] {processor.py:743} INFO - Processing file /opt/airflow/dags/s3_to_snowflake.py for tasks to queue
[2023-03-06T12:26:26.074+0000] {logging_mixin.py:137} INFO - [2023-03-06T12:26:26.073+0000] {dagbag.py:538} INFO - Filling up the DagBag from /opt/airflow/dags/s3_to_snowflake.py
[2023-03-06T12:26:26.086+0000] {logging_mixin.py:137} INFO - [2023-03-06T12:26:26.085+0000] {dagbag.py:343} ERROR - Failed to import: /opt/airflow/dags/s3_to_snowflake.py
Traceback (most recent call last):
  File "/home/airflow/.local/lib/python3.7/site-packages/airflow/models/dagbag.py", line 339, in parse
    loader.exec_module(new_module)
  File "<frozen importlib._bootstrap_external>", line 728, in exec_module
  File "<frozen importlib._bootstrap>", line 219, in _call_with_frames_removed
  File "/opt/airflow/dags/s3_to_snowflake.py", line 6, in <module>
    from airflow.providers.snowflake.operators.snowflake import SnowflakeOperator
ModuleNotFoundError: No module named 'airflow.providers.snowflake'
[2023-03-06T12:26:26.086+0000] {processor.py:755} WARNING - No viable dags retrieved from /opt/airflow/dags/s3_to_snowflake.py
[2023-03-06T12:26:26.099+0000] {processor.py:175} INFO - Processing /opt/airflow/dags/s3_to_snowflake.py took 0.028 seconds
[2023-03-06T12:26:56.204+0000] {processor.py:153} INFO - Started process (PID=1696) to work on /opt/airflow/dags/s3_to_snowflake.py
[2023-03-06T12:26:56.205+0000] {processor.py:743} INFO - Processing file /opt/airflow/dags/s3_to_snowflake.py for tasks to queue
[2023-03-06T12:26:56.205+0000] {logging_mixin.py:137} INFO - [2023-03-06T12:26:56.205+0000] {dagbag.py:538} INFO - Filling up the DagBag from /opt/airflow/dags/s3_to_snowflake.py
[2023-03-06T12:26:56.216+0000] {logging_mixin.py:137} INFO - [2023-03-06T12:26:56.215+0000] {dagbag.py:343} ERROR - Failed to import: /opt/airflow/dags/s3_to_snowflake.py
Traceback (most recent call last):
  File "/home/airflow/.local/lib/python3.7/site-packages/airflow/models/dagbag.py", line 339, in parse
    loader.exec_module(new_module)
  File "<frozen importlib._bootstrap_external>", line 728, in exec_module
  File "<frozen importlib._bootstrap>", line 219, in _call_with_frames_removed
  File "/opt/airflow/dags/s3_to_snowflake.py", line 6, in <module>
    from airflow.providers.snowflake.operators.snowflake import SnowflakeOperator
ModuleNotFoundError: No module named 'airflow.providers.snowflake'
[2023-03-06T12:26:56.216+0000] {processor.py:755} WARNING - No viable dags retrieved from /opt/airflow/dags/s3_to_snowflake.py
[2023-03-06T12:26:56.229+0000] {processor.py:175} INFO - Processing /opt/airflow/dags/s3_to_snowflake.py took 0.026 seconds
[2023-03-06T12:27:26.332+0000] {processor.py:153} INFO - Started process (PID=1758) to work on /opt/airflow/dags/s3_to_snowflake.py
[2023-03-06T12:27:26.333+0000] {processor.py:743} INFO - Processing file /opt/airflow/dags/s3_to_snowflake.py for tasks to queue
[2023-03-06T12:27:26.334+0000] {logging_mixin.py:137} INFO - [2023-03-06T12:27:26.334+0000] {dagbag.py:538} INFO - Filling up the DagBag from /opt/airflow/dags/s3_to_snowflake.py
[2023-03-06T12:27:26.344+0000] {logging_mixin.py:137} INFO - [2023-03-06T12:27:26.344+0000] {dagbag.py:343} ERROR - Failed to import: /opt/airflow/dags/s3_to_snowflake.py
Traceback (most recent call last):
  File "/home/airflow/.local/lib/python3.7/site-packages/airflow/models/dagbag.py", line 339, in parse
    loader.exec_module(new_module)
  File "<frozen importlib._bootstrap_external>", line 728, in exec_module
  File "<frozen importlib._bootstrap>", line 219, in _call_with_frames_removed
  File "/opt/airflow/dags/s3_to_snowflake.py", line 6, in <module>
    from airflow.providers.snowflake.operators.snowflake import SnowflakeOperator
ModuleNotFoundError: No module named 'airflow.providers.snowflake'
[2023-03-06T12:27:26.345+0000] {processor.py:755} WARNING - No viable dags retrieved from /opt/airflow/dags/s3_to_snowflake.py
[2023-03-06T12:27:26.359+0000] {processor.py:175} INFO - Processing /opt/airflow/dags/s3_to_snowflake.py took 0.028 seconds
[2023-03-06T12:27:56.456+0000] {processor.py:153} INFO - Started process (PID=1800) to work on /opt/airflow/dags/s3_to_snowflake.py
[2023-03-06T12:27:56.456+0000] {processor.py:743} INFO - Processing file /opt/airflow/dags/s3_to_snowflake.py for tasks to queue
[2023-03-06T12:27:56.457+0000] {logging_mixin.py:137} INFO - [2023-03-06T12:27:56.457+0000] {dagbag.py:538} INFO - Filling up the DagBag from /opt/airflow/dags/s3_to_snowflake.py
[2023-03-06T12:27:56.467+0000] {logging_mixin.py:137} INFO - [2023-03-06T12:27:56.466+0000] {dagbag.py:343} ERROR - Failed to import: /opt/airflow/dags/s3_to_snowflake.py
Traceback (most recent call last):
  File "/home/airflow/.local/lib/python3.7/site-packages/airflow/models/dagbag.py", line 339, in parse
    loader.exec_module(new_module)
  File "<frozen importlib._bootstrap_external>", line 728, in exec_module
  File "<frozen importlib._bootstrap>", line 219, in _call_with_frames_removed
  File "/opt/airflow/dags/s3_to_snowflake.py", line 6, in <module>
    from airflow.providers.snowflake.operators.snowflake import SnowflakeOperator
ModuleNotFoundError: No module named 'airflow.providers.snowflake'
[2023-03-06T12:27:56.467+0000] {processor.py:755} WARNING - No viable dags retrieved from /opt/airflow/dags/s3_to_snowflake.py
[2023-03-06T12:27:56.482+0000] {processor.py:175} INFO - Processing /opt/airflow/dags/s3_to_snowflake.py took 0.027 seconds
[2023-03-06T12:28:26.578+0000] {processor.py:153} INFO - Started process (PID=1862) to work on /opt/airflow/dags/s3_to_snowflake.py
[2023-03-06T12:28:26.579+0000] {processor.py:743} INFO - Processing file /opt/airflow/dags/s3_to_snowflake.py for tasks to queue
[2023-03-06T12:28:26.579+0000] {logging_mixin.py:137} INFO - [2023-03-06T12:28:26.579+0000] {dagbag.py:538} INFO - Filling up the DagBag from /opt/airflow/dags/s3_to_snowflake.py
[2023-03-06T12:28:26.588+0000] {logging_mixin.py:137} INFO - [2023-03-06T12:28:26.588+0000] {dagbag.py:343} ERROR - Failed to import: /opt/airflow/dags/s3_to_snowflake.py
Traceback (most recent call last):
  File "/home/airflow/.local/lib/python3.7/site-packages/airflow/models/dagbag.py", line 339, in parse
    loader.exec_module(new_module)
  File "<frozen importlib._bootstrap_external>", line 728, in exec_module
  File "<frozen importlib._bootstrap>", line 219, in _call_with_frames_removed
  File "/opt/airflow/dags/s3_to_snowflake.py", line 6, in <module>
    from airflow.providers.snowflake.operators.snowflake import SnowflakeOperator
ModuleNotFoundError: No module named 'airflow.providers.snowflake'
[2023-03-06T12:28:26.589+0000] {processor.py:755} WARNING - No viable dags retrieved from /opt/airflow/dags/s3_to_snowflake.py
[2023-03-06T12:28:26.601+0000] {processor.py:175} INFO - Processing /opt/airflow/dags/s3_to_snowflake.py took 0.025 seconds
[2023-03-06T12:28:56.703+0000] {processor.py:153} INFO - Started process (PID=1904) to work on /opt/airflow/dags/s3_to_snowflake.py
[2023-03-06T12:28:56.703+0000] {processor.py:743} INFO - Processing file /opt/airflow/dags/s3_to_snowflake.py for tasks to queue
[2023-03-06T12:28:56.703+0000] {logging_mixin.py:137} INFO - [2023-03-06T12:28:56.703+0000] {dagbag.py:538} INFO - Filling up the DagBag from /opt/airflow/dags/s3_to_snowflake.py
[2023-03-06T12:28:56.715+0000] {logging_mixin.py:137} INFO - [2023-03-06T12:28:56.714+0000] {dagbag.py:343} ERROR - Failed to import: /opt/airflow/dags/s3_to_snowflake.py
Traceback (most recent call last):
  File "/home/airflow/.local/lib/python3.7/site-packages/airflow/models/dagbag.py", line 339, in parse
    loader.exec_module(new_module)
  File "<frozen importlib._bootstrap_external>", line 728, in exec_module
  File "<frozen importlib._bootstrap>", line 219, in _call_with_frames_removed
  File "/opt/airflow/dags/s3_to_snowflake.py", line 6, in <module>
    from airflow.providers.snowflake.operators.snowflake import SnowflakeOperator
ModuleNotFoundError: No module named 'airflow.providers.snowflake'
[2023-03-06T12:28:56.715+0000] {processor.py:755} WARNING - No viable dags retrieved from /opt/airflow/dags/s3_to_snowflake.py
[2023-03-06T12:28:56.727+0000] {processor.py:175} INFO - Processing /opt/airflow/dags/s3_to_snowflake.py took 0.026 seconds
[2023-03-06T12:29:26.821+0000] {processor.py:153} INFO - Started process (PID=1966) to work on /opt/airflow/dags/s3_to_snowflake.py
[2023-03-06T12:29:26.821+0000] {processor.py:743} INFO - Processing file /opt/airflow/dags/s3_to_snowflake.py for tasks to queue
[2023-03-06T12:29:26.822+0000] {logging_mixin.py:137} INFO - [2023-03-06T12:29:26.822+0000] {dagbag.py:538} INFO - Filling up the DagBag from /opt/airflow/dags/s3_to_snowflake.py
[2023-03-06T12:29:26.832+0000] {logging_mixin.py:137} INFO - [2023-03-06T12:29:26.832+0000] {dagbag.py:343} ERROR - Failed to import: /opt/airflow/dags/s3_to_snowflake.py
Traceback (most recent call last):
  File "/home/airflow/.local/lib/python3.7/site-packages/airflow/models/dagbag.py", line 339, in parse
    loader.exec_module(new_module)
  File "<frozen importlib._bootstrap_external>", line 728, in exec_module
  File "<frozen importlib._bootstrap>", line 219, in _call_with_frames_removed
  File "/opt/airflow/dags/s3_to_snowflake.py", line 6, in <module>
    from airflow.providers.snowflake.operators.snowflake import SnowflakeOperator
ModuleNotFoundError: No module named 'airflow.providers.snowflake'
[2023-03-06T12:29:26.832+0000] {processor.py:755} WARNING - No viable dags retrieved from /opt/airflow/dags/s3_to_snowflake.py
[2023-03-06T12:29:26.845+0000] {processor.py:175} INFO - Processing /opt/airflow/dags/s3_to_snowflake.py took 0.026 seconds
[2023-03-06T12:29:56.937+0000] {processor.py:153} INFO - Started process (PID=2008) to work on /opt/airflow/dags/s3_to_snowflake.py
[2023-03-06T12:29:56.938+0000] {processor.py:743} INFO - Processing file /opt/airflow/dags/s3_to_snowflake.py for tasks to queue
[2023-03-06T12:29:56.938+0000] {logging_mixin.py:137} INFO - [2023-03-06T12:29:56.938+0000] {dagbag.py:538} INFO - Filling up the DagBag from /opt/airflow/dags/s3_to_snowflake.py
[2023-03-06T12:29:56.950+0000] {logging_mixin.py:137} INFO - [2023-03-06T12:29:56.949+0000] {dagbag.py:343} ERROR - Failed to import: /opt/airflow/dags/s3_to_snowflake.py
Traceback (most recent call last):
  File "/home/airflow/.local/lib/python3.7/site-packages/airflow/models/dagbag.py", line 339, in parse
    loader.exec_module(new_module)
  File "<frozen importlib._bootstrap_external>", line 728, in exec_module
  File "<frozen importlib._bootstrap>", line 219, in _call_with_frames_removed
  File "/opt/airflow/dags/s3_to_snowflake.py", line 6, in <module>
    from airflow.providers.snowflake.operators.snowflake import SnowflakeOperator
ModuleNotFoundError: No module named 'airflow.providers.snowflake'
[2023-03-06T12:29:56.950+0000] {processor.py:755} WARNING - No viable dags retrieved from /opt/airflow/dags/s3_to_snowflake.py
[2023-03-06T12:29:56.963+0000] {processor.py:175} INFO - Processing /opt/airflow/dags/s3_to_snowflake.py took 0.028 seconds
[2023-03-06T12:30:27.059+0000] {processor.py:153} INFO - Started process (PID=2070) to work on /opt/airflow/dags/s3_to_snowflake.py
[2023-03-06T12:30:27.059+0000] {processor.py:743} INFO - Processing file /opt/airflow/dags/s3_to_snowflake.py for tasks to queue
[2023-03-06T12:30:27.060+0000] {logging_mixin.py:137} INFO - [2023-03-06T12:30:27.060+0000] {dagbag.py:538} INFO - Filling up the DagBag from /opt/airflow/dags/s3_to_snowflake.py
[2023-03-06T12:30:27.069+0000] {logging_mixin.py:137} INFO - [2023-03-06T12:30:27.069+0000] {dagbag.py:343} ERROR - Failed to import: /opt/airflow/dags/s3_to_snowflake.py
Traceback (most recent call last):
  File "/home/airflow/.local/lib/python3.7/site-packages/airflow/models/dagbag.py", line 339, in parse
    loader.exec_module(new_module)
  File "<frozen importlib._bootstrap_external>", line 728, in exec_module
  File "<frozen importlib._bootstrap>", line 219, in _call_with_frames_removed
  File "/opt/airflow/dags/s3_to_snowflake.py", line 6, in <module>
    from airflow.providers.snowflake.operators.snowflake import SnowflakeOperator
ModuleNotFoundError: No module named 'airflow.providers.snowflake'
[2023-03-06T12:30:27.069+0000] {processor.py:755} WARNING - No viable dags retrieved from /opt/airflow/dags/s3_to_snowflake.py
[2023-03-06T12:30:27.083+0000] {processor.py:175} INFO - Processing /opt/airflow/dags/s3_to_snowflake.py took 0.026 seconds
[2023-03-06T12:30:57.180+0000] {processor.py:153} INFO - Started process (PID=2112) to work on /opt/airflow/dags/s3_to_snowflake.py
[2023-03-06T12:30:57.180+0000] {processor.py:743} INFO - Processing file /opt/airflow/dags/s3_to_snowflake.py for tasks to queue
[2023-03-06T12:30:57.181+0000] {logging_mixin.py:137} INFO - [2023-03-06T12:30:57.181+0000] {dagbag.py:538} INFO - Filling up the DagBag from /opt/airflow/dags/s3_to_snowflake.py
[2023-03-06T12:30:57.190+0000] {logging_mixin.py:137} INFO - [2023-03-06T12:30:57.190+0000] {dagbag.py:343} ERROR - Failed to import: /opt/airflow/dags/s3_to_snowflake.py
Traceback (most recent call last):
  File "/home/airflow/.local/lib/python3.7/site-packages/airflow/models/dagbag.py", line 339, in parse
    loader.exec_module(new_module)
  File "<frozen importlib._bootstrap_external>", line 728, in exec_module
  File "<frozen importlib._bootstrap>", line 219, in _call_with_frames_removed
  File "/opt/airflow/dags/s3_to_snowflake.py", line 6, in <module>
    from airflow.providers.snowflake.operators.snowflake import SnowflakeOperator
ModuleNotFoundError: No module named 'airflow.providers.snowflake'
[2023-03-06T12:30:57.190+0000] {processor.py:755} WARNING - No viable dags retrieved from /opt/airflow/dags/s3_to_snowflake.py
[2023-03-06T12:30:57.266+0000] {processor.py:175} INFO - Processing /opt/airflow/dags/s3_to_snowflake.py took 0.087 seconds
[2023-03-06T12:31:27.367+0000] {processor.py:153} INFO - Started process (PID=2174) to work on /opt/airflow/dags/s3_to_snowflake.py
[2023-03-06T12:31:27.369+0000] {processor.py:743} INFO - Processing file /opt/airflow/dags/s3_to_snowflake.py for tasks to queue
[2023-03-06T12:31:27.369+0000] {logging_mixin.py:137} INFO - [2023-03-06T12:31:27.369+0000] {dagbag.py:538} INFO - Filling up the DagBag from /opt/airflow/dags/s3_to_snowflake.py
[2023-03-06T12:31:27.379+0000] {logging_mixin.py:137} INFO - [2023-03-06T12:31:27.379+0000] {dagbag.py:343} ERROR - Failed to import: /opt/airflow/dags/s3_to_snowflake.py
Traceback (most recent call last):
  File "/home/airflow/.local/lib/python3.7/site-packages/airflow/models/dagbag.py", line 339, in parse
    loader.exec_module(new_module)
  File "<frozen importlib._bootstrap_external>", line 728, in exec_module
  File "<frozen importlib._bootstrap>", line 219, in _call_with_frames_removed
  File "/opt/airflow/dags/s3_to_snowflake.py", line 6, in <module>
    from airflow.providers.snowflake.operators.snowflake import SnowflakeOperator
ModuleNotFoundError: No module named 'airflow.providers.snowflake'
[2023-03-06T12:31:27.379+0000] {processor.py:755} WARNING - No viable dags retrieved from /opt/airflow/dags/s3_to_snowflake.py
[2023-03-06T12:31:27.392+0000] {processor.py:175} INFO - Processing /opt/airflow/dags/s3_to_snowflake.py took 0.027 seconds
[2023-03-06T12:31:57.492+0000] {processor.py:153} INFO - Started process (PID=2237) to work on /opt/airflow/dags/s3_to_snowflake.py
[2023-03-06T12:31:57.492+0000] {processor.py:743} INFO - Processing file /opt/airflow/dags/s3_to_snowflake.py for tasks to queue
[2023-03-06T12:31:57.492+0000] {logging_mixin.py:137} INFO - [2023-03-06T12:31:57.492+0000] {dagbag.py:538} INFO - Filling up the DagBag from /opt/airflow/dags/s3_to_snowflake.py
[2023-03-06T12:31:57.503+0000] {logging_mixin.py:137} INFO - [2023-03-06T12:31:57.503+0000] {dagbag.py:343} ERROR - Failed to import: /opt/airflow/dags/s3_to_snowflake.py
Traceback (most recent call last):
  File "/home/airflow/.local/lib/python3.7/site-packages/airflow/models/dagbag.py", line 339, in parse
    loader.exec_module(new_module)
  File "<frozen importlib._bootstrap_external>", line 728, in exec_module
  File "<frozen importlib._bootstrap>", line 219, in _call_with_frames_removed
  File "/opt/airflow/dags/s3_to_snowflake.py", line 6, in <module>
    from airflow.providers.snowflake.operators.snowflake import SnowflakeOperator
ModuleNotFoundError: No module named 'airflow.providers.snowflake'
[2023-03-06T12:31:57.503+0000] {processor.py:755} WARNING - No viable dags retrieved from /opt/airflow/dags/s3_to_snowflake.py
[2023-03-06T12:31:57.516+0000] {processor.py:175} INFO - Processing /opt/airflow/dags/s3_to_snowflake.py took 0.027 seconds
[2023-03-06T12:32:27.610+0000] {processor.py:153} INFO - Started process (PID=2279) to work on /opt/airflow/dags/s3_to_snowflake.py
[2023-03-06T12:32:27.610+0000] {processor.py:743} INFO - Processing file /opt/airflow/dags/s3_to_snowflake.py for tasks to queue
[2023-03-06T12:32:27.611+0000] {logging_mixin.py:137} INFO - [2023-03-06T12:32:27.611+0000] {dagbag.py:538} INFO - Filling up the DagBag from /opt/airflow/dags/s3_to_snowflake.py
[2023-03-06T12:32:27.620+0000] {logging_mixin.py:137} INFO - [2023-03-06T12:32:27.620+0000] {dagbag.py:343} ERROR - Failed to import: /opt/airflow/dags/s3_to_snowflake.py
Traceback (most recent call last):
  File "/home/airflow/.local/lib/python3.7/site-packages/airflow/models/dagbag.py", line 339, in parse
    loader.exec_module(new_module)
  File "<frozen importlib._bootstrap_external>", line 728, in exec_module
  File "<frozen importlib._bootstrap>", line 219, in _call_with_frames_removed
  File "/opt/airflow/dags/s3_to_snowflake.py", line 6, in <module>
    from airflow.providers.snowflake.operators.snowflake import SnowflakeOperator
ModuleNotFoundError: No module named 'airflow.providers.snowflake'
[2023-03-06T12:32:27.620+0000] {processor.py:755} WARNING - No viable dags retrieved from /opt/airflow/dags/s3_to_snowflake.py
[2023-03-06T12:32:27.634+0000] {processor.py:175} INFO - Processing /opt/airflow/dags/s3_to_snowflake.py took 0.026 seconds
[2023-03-06T12:32:57.802+0000] {processor.py:153} INFO - Started process (PID=2341) to work on /opt/airflow/dags/s3_to_snowflake.py
[2023-03-06T12:32:57.803+0000] {processor.py:743} INFO - Processing file /opt/airflow/dags/s3_to_snowflake.py for tasks to queue
[2023-03-06T12:32:57.803+0000] {logging_mixin.py:137} INFO - [2023-03-06T12:32:57.803+0000] {dagbag.py:538} INFO - Filling up the DagBag from /opt/airflow/dags/s3_to_snowflake.py
[2023-03-06T12:32:57.820+0000] {logging_mixin.py:137} INFO - [2023-03-06T12:32:57.819+0000] {dagbag.py:343} ERROR - Failed to import: /opt/airflow/dags/s3_to_snowflake.py
Traceback (most recent call last):
  File "/home/airflow/.local/lib/python3.7/site-packages/airflow/models/dagbag.py", line 339, in parse
    loader.exec_module(new_module)
  File "<frozen importlib._bootstrap_external>", line 728, in exec_module
  File "<frozen importlib._bootstrap>", line 219, in _call_with_frames_removed
  File "/opt/airflow/dags/s3_to_snowflake.py", line 6, in <module>
    from airflow.providers.snowflake.operators.snowflake import SnowflakeOperator
ModuleNotFoundError: No module named 'airflow.providers.snowflake'
[2023-03-06T12:32:57.821+0000] {processor.py:755} WARNING - No viable dags retrieved from /opt/airflow/dags/s3_to_snowflake.py
[2023-03-06T12:32:57.838+0000] {processor.py:175} INFO - Processing /opt/airflow/dags/s3_to_snowflake.py took 0.039 seconds
[2023-03-06T12:33:27.929+0000] {processor.py:153} INFO - Started process (PID=2383) to work on /opt/airflow/dags/s3_to_snowflake.py
[2023-03-06T12:33:27.929+0000] {processor.py:743} INFO - Processing file /opt/airflow/dags/s3_to_snowflake.py for tasks to queue
[2023-03-06T12:33:27.929+0000] {logging_mixin.py:137} INFO - [2023-03-06T12:33:27.929+0000] {dagbag.py:538} INFO - Filling up the DagBag from /opt/airflow/dags/s3_to_snowflake.py
[2023-03-06T12:33:27.940+0000] {logging_mixin.py:137} INFO - [2023-03-06T12:33:27.939+0000] {dagbag.py:343} ERROR - Failed to import: /opt/airflow/dags/s3_to_snowflake.py
Traceback (most recent call last):
  File "/home/airflow/.local/lib/python3.7/site-packages/airflow/models/dagbag.py", line 339, in parse
    loader.exec_module(new_module)
  File "<frozen importlib._bootstrap_external>", line 728, in exec_module
  File "<frozen importlib._bootstrap>", line 219, in _call_with_frames_removed
  File "/opt/airflow/dags/s3_to_snowflake.py", line 6, in <module>
    from airflow.providers.snowflake.operators.snowflake import SnowflakeOperator
ModuleNotFoundError: No module named 'airflow.providers.snowflake'
[2023-03-06T12:33:27.940+0000] {processor.py:755} WARNING - No viable dags retrieved from /opt/airflow/dags/s3_to_snowflake.py
[2023-03-06T12:33:27.954+0000] {processor.py:175} INFO - Processing /opt/airflow/dags/s3_to_snowflake.py took 0.028 seconds
[2023-03-06T12:33:58.048+0000] {processor.py:153} INFO - Started process (PID=2445) to work on /opt/airflow/dags/s3_to_snowflake.py
[2023-03-06T12:33:58.048+0000] {processor.py:743} INFO - Processing file /opt/airflow/dags/s3_to_snowflake.py for tasks to queue
[2023-03-06T12:33:58.049+0000] {logging_mixin.py:137} INFO - [2023-03-06T12:33:58.048+0000] {dagbag.py:538} INFO - Filling up the DagBag from /opt/airflow/dags/s3_to_snowflake.py
[2023-03-06T12:33:58.058+0000] {logging_mixin.py:137} INFO - [2023-03-06T12:33:58.057+0000] {dagbag.py:343} ERROR - Failed to import: /opt/airflow/dags/s3_to_snowflake.py
Traceback (most recent call last):
  File "/home/airflow/.local/lib/python3.7/site-packages/airflow/models/dagbag.py", line 339, in parse
    loader.exec_module(new_module)
  File "<frozen importlib._bootstrap_external>", line 728, in exec_module
  File "<frozen importlib._bootstrap>", line 219, in _call_with_frames_removed
  File "/opt/airflow/dags/s3_to_snowflake.py", line 6, in <module>
    from airflow.providers.snowflake.operators.snowflake import SnowflakeOperator
ModuleNotFoundError: No module named 'airflow.providers.snowflake'
[2023-03-06T12:33:58.058+0000] {processor.py:755} WARNING - No viable dags retrieved from /opt/airflow/dags/s3_to_snowflake.py
[2023-03-06T12:33:58.071+0000] {processor.py:175} INFO - Processing /opt/airflow/dags/s3_to_snowflake.py took 0.025 seconds
[2023-03-06T12:34:28.163+0000] {processor.py:153} INFO - Started process (PID=2487) to work on /opt/airflow/dags/s3_to_snowflake.py
[2023-03-06T12:34:28.171+0000] {processor.py:743} INFO - Processing file /opt/airflow/dags/s3_to_snowflake.py for tasks to queue
[2023-03-06T12:34:28.172+0000] {logging_mixin.py:137} INFO - [2023-03-06T12:34:28.172+0000] {dagbag.py:538} INFO - Filling up the DagBag from /opt/airflow/dags/s3_to_snowflake.py
[2023-03-06T12:34:28.182+0000] {logging_mixin.py:137} INFO - [2023-03-06T12:34:28.181+0000] {dagbag.py:343} ERROR - Failed to import: /opt/airflow/dags/s3_to_snowflake.py
Traceback (most recent call last):
  File "/home/airflow/.local/lib/python3.7/site-packages/airflow/models/dagbag.py", line 339, in parse
    loader.exec_module(new_module)
  File "<frozen importlib._bootstrap_external>", line 728, in exec_module
  File "<frozen importlib._bootstrap>", line 219, in _call_with_frames_removed
  File "/opt/airflow/dags/s3_to_snowflake.py", line 6, in <module>
    from airflow.providers.snowflake.operators.snowflake import SnowflakeOperator
ModuleNotFoundError: No module named 'airflow.providers.snowflake'
[2023-03-06T12:34:28.182+0000] {processor.py:755} WARNING - No viable dags retrieved from /opt/airflow/dags/s3_to_snowflake.py
[2023-03-06T12:34:28.194+0000] {processor.py:175} INFO - Processing /opt/airflow/dags/s3_to_snowflake.py took 0.033 seconds
[2023-03-06T12:34:58.289+0000] {processor.py:153} INFO - Started process (PID=2549) to work on /opt/airflow/dags/s3_to_snowflake.py
[2023-03-06T12:34:58.289+0000] {processor.py:743} INFO - Processing file /opt/airflow/dags/s3_to_snowflake.py for tasks to queue
[2023-03-06T12:34:58.290+0000] {logging_mixin.py:137} INFO - [2023-03-06T12:34:58.290+0000] {dagbag.py:538} INFO - Filling up the DagBag from /opt/airflow/dags/s3_to_snowflake.py
[2023-03-06T12:34:58.299+0000] {logging_mixin.py:137} INFO - [2023-03-06T12:34:58.299+0000] {dagbag.py:343} ERROR - Failed to import: /opt/airflow/dags/s3_to_snowflake.py
Traceback (most recent call last):
  File "/home/airflow/.local/lib/python3.7/site-packages/airflow/models/dagbag.py", line 339, in parse
    loader.exec_module(new_module)
  File "<frozen importlib._bootstrap_external>", line 728, in exec_module
  File "<frozen importlib._bootstrap>", line 219, in _call_with_frames_removed
  File "/opt/airflow/dags/s3_to_snowflake.py", line 6, in <module>
    from airflow.providers.snowflake.operators.snowflake import SnowflakeOperator
ModuleNotFoundError: No module named 'airflow.providers.snowflake'
[2023-03-06T12:34:58.300+0000] {processor.py:755} WARNING - No viable dags retrieved from /opt/airflow/dags/s3_to_snowflake.py
[2023-03-06T12:34:58.314+0000] {processor.py:175} INFO - Processing /opt/airflow/dags/s3_to_snowflake.py took 0.026 seconds
[2023-03-06T12:35:28.403+0000] {processor.py:153} INFO - Started process (PID=2591) to work on /opt/airflow/dags/s3_to_snowflake.py
[2023-03-06T12:35:28.411+0000] {processor.py:743} INFO - Processing file /opt/airflow/dags/s3_to_snowflake.py for tasks to queue
[2023-03-06T12:35:28.411+0000] {logging_mixin.py:137} INFO - [2023-03-06T12:35:28.411+0000] {dagbag.py:538} INFO - Filling up the DagBag from /opt/airflow/dags/s3_to_snowflake.py
[2023-03-06T12:35:28.422+0000] {logging_mixin.py:137} INFO - [2023-03-06T12:35:28.422+0000] {dagbag.py:343} ERROR - Failed to import: /opt/airflow/dags/s3_to_snowflake.py
Traceback (most recent call last):
  File "/home/airflow/.local/lib/python3.7/site-packages/airflow/models/dagbag.py", line 339, in parse
    loader.exec_module(new_module)
  File "<frozen importlib._bootstrap_external>", line 728, in exec_module
  File "<frozen importlib._bootstrap>", line 219, in _call_with_frames_removed
  File "/opt/airflow/dags/s3_to_snowflake.py", line 6, in <module>
    from airflow.providers.snowflake.operators.snowflake import SnowflakeOperator
ModuleNotFoundError: No module named 'airflow.providers.snowflake'
[2023-03-06T12:35:28.422+0000] {processor.py:755} WARNING - No viable dags retrieved from /opt/airflow/dags/s3_to_snowflake.py
[2023-03-06T12:35:28.434+0000] {processor.py:175} INFO - Processing /opt/airflow/dags/s3_to_snowflake.py took 0.033 seconds
[2023-03-06T12:35:58.524+0000] {processor.py:153} INFO - Started process (PID=2654) to work on /opt/airflow/dags/s3_to_snowflake.py
[2023-03-06T12:35:58.525+0000] {processor.py:743} INFO - Processing file /opt/airflow/dags/s3_to_snowflake.py for tasks to queue
[2023-03-06T12:35:58.525+0000] {logging_mixin.py:137} INFO - [2023-03-06T12:35:58.525+0000] {dagbag.py:538} INFO - Filling up the DagBag from /opt/airflow/dags/s3_to_snowflake.py
[2023-03-06T12:35:58.536+0000] {logging_mixin.py:137} INFO - [2023-03-06T12:35:58.535+0000] {dagbag.py:343} ERROR - Failed to import: /opt/airflow/dags/s3_to_snowflake.py
Traceback (most recent call last):
  File "/home/airflow/.local/lib/python3.7/site-packages/airflow/models/dagbag.py", line 339, in parse
    loader.exec_module(new_module)
  File "<frozen importlib._bootstrap_external>", line 728, in exec_module
  File "<frozen importlib._bootstrap>", line 219, in _call_with_frames_removed
  File "/opt/airflow/dags/s3_to_snowflake.py", line 6, in <module>
    from airflow.providers.snowflake.operators.snowflake import SnowflakeOperator
ModuleNotFoundError: No module named 'airflow.providers.snowflake'
[2023-03-06T12:35:58.536+0000] {processor.py:755} WARNING - No viable dags retrieved from /opt/airflow/dags/s3_to_snowflake.py
[2023-03-06T12:35:58.548+0000] {processor.py:175} INFO - Processing /opt/airflow/dags/s3_to_snowflake.py took 0.026 seconds
[2023-03-06T12:36:28.659+0000] {processor.py:153} INFO - Started process (PID=2696) to work on /opt/airflow/dags/s3_to_snowflake.py
[2023-03-06T12:36:28.666+0000] {processor.py:743} INFO - Processing file /opt/airflow/dags/s3_to_snowflake.py for tasks to queue
[2023-03-06T12:36:28.667+0000] {logging_mixin.py:137} INFO - [2023-03-06T12:36:28.667+0000] {dagbag.py:538} INFO - Filling up the DagBag from /opt/airflow/dags/s3_to_snowflake.py
[2023-03-06T12:36:28.677+0000] {logging_mixin.py:137} INFO - [2023-03-06T12:36:28.676+0000] {dagbag.py:343} ERROR - Failed to import: /opt/airflow/dags/s3_to_snowflake.py
Traceback (most recent call last):
  File "/home/airflow/.local/lib/python3.7/site-packages/airflow/models/dagbag.py", line 339, in parse
    loader.exec_module(new_module)
  File "<frozen importlib._bootstrap_external>", line 728, in exec_module
  File "<frozen importlib._bootstrap>", line 219, in _call_with_frames_removed
  File "/opt/airflow/dags/s3_to_snowflake.py", line 6, in <module>
    from airflow.providers.snowflake.operators.snowflake import SnowflakeOperator
ModuleNotFoundError: No module named 'airflow.providers.snowflake'
[2023-03-06T12:36:28.677+0000] {processor.py:755} WARNING - No viable dags retrieved from /opt/airflow/dags/s3_to_snowflake.py
[2023-03-06T12:36:28.690+0000] {processor.py:175} INFO - Processing /opt/airflow/dags/s3_to_snowflake.py took 0.034 seconds
[2023-03-06T12:36:58.775+0000] {processor.py:153} INFO - Started process (PID=2758) to work on /opt/airflow/dags/s3_to_snowflake.py
[2023-03-06T12:36:58.776+0000] {processor.py:743} INFO - Processing file /opt/airflow/dags/s3_to_snowflake.py for tasks to queue
[2023-03-06T12:36:58.776+0000] {logging_mixin.py:137} INFO - [2023-03-06T12:36:58.776+0000] {dagbag.py:538} INFO - Filling up the DagBag from /opt/airflow/dags/s3_to_snowflake.py
[2023-03-06T12:36:58.786+0000] {logging_mixin.py:137} INFO - [2023-03-06T12:36:58.785+0000] {dagbag.py:343} ERROR - Failed to import: /opt/airflow/dags/s3_to_snowflake.py
Traceback (most recent call last):
  File "/home/airflow/.local/lib/python3.7/site-packages/airflow/models/dagbag.py", line 339, in parse
    loader.exec_module(new_module)
  File "<frozen importlib._bootstrap_external>", line 728, in exec_module
  File "<frozen importlib._bootstrap>", line 219, in _call_with_frames_removed
  File "/opt/airflow/dags/s3_to_snowflake.py", line 6, in <module>
    from airflow.providers.snowflake.operators.snowflake import SnowflakeOperator
ModuleNotFoundError: No module named 'airflow.providers.snowflake'
[2023-03-06T12:36:58.786+0000] {processor.py:755} WARNING - No viable dags retrieved from /opt/airflow/dags/s3_to_snowflake.py
[2023-03-06T12:36:58.798+0000] {processor.py:175} INFO - Processing /opt/airflow/dags/s3_to_snowflake.py took 0.024 seconds
[2023-03-06T12:37:28.921+0000] {processor.py:153} INFO - Started process (PID=2819) to work on /opt/airflow/dags/s3_to_snowflake.py
[2023-03-06T12:37:28.929+0000] {processor.py:743} INFO - Processing file /opt/airflow/dags/s3_to_snowflake.py for tasks to queue
[2023-03-06T12:37:28.929+0000] {logging_mixin.py:137} INFO - [2023-03-06T12:37:28.929+0000] {dagbag.py:538} INFO - Filling up the DagBag from /opt/airflow/dags/s3_to_snowflake.py
[2023-03-06T12:37:28.940+0000] {logging_mixin.py:137} INFO - [2023-03-06T12:37:28.940+0000] {dagbag.py:343} ERROR - Failed to import: /opt/airflow/dags/s3_to_snowflake.py
Traceback (most recent call last):
  File "/home/airflow/.local/lib/python3.7/site-packages/airflow/models/dagbag.py", line 339, in parse
    loader.exec_module(new_module)
  File "<frozen importlib._bootstrap_external>", line 728, in exec_module
  File "<frozen importlib._bootstrap>", line 219, in _call_with_frames_removed
  File "/opt/airflow/dags/s3_to_snowflake.py", line 6, in <module>
    from airflow.providers.snowflake.operators.snowflake import SnowflakeOperator
ModuleNotFoundError: No module named 'airflow.providers.snowflake'
[2023-03-06T12:37:28.941+0000] {processor.py:755} WARNING - No viable dags retrieved from /opt/airflow/dags/s3_to_snowflake.py
[2023-03-06T12:37:28.955+0000] {processor.py:175} INFO - Processing /opt/airflow/dags/s3_to_snowflake.py took 0.037 seconds
[2023-03-06T12:37:59.081+0000] {processor.py:153} INFO - Started process (PID=2861) to work on /opt/airflow/dags/s3_to_snowflake.py
[2023-03-06T12:37:59.082+0000] {processor.py:743} INFO - Processing file /opt/airflow/dags/s3_to_snowflake.py for tasks to queue
[2023-03-06T12:37:59.082+0000] {logging_mixin.py:137} INFO - [2023-03-06T12:37:59.082+0000] {dagbag.py:538} INFO - Filling up the DagBag from /opt/airflow/dags/s3_to_snowflake.py
[2023-03-06T12:37:59.093+0000] {logging_mixin.py:137} INFO - [2023-03-06T12:37:59.092+0000] {dagbag.py:343} ERROR - Failed to import: /opt/airflow/dags/s3_to_snowflake.py
Traceback (most recent call last):
  File "/home/airflow/.local/lib/python3.7/site-packages/airflow/models/dagbag.py", line 339, in parse
    loader.exec_module(new_module)
  File "<frozen importlib._bootstrap_external>", line 728, in exec_module
  File "<frozen importlib._bootstrap>", line 219, in _call_with_frames_removed
  File "/opt/airflow/dags/s3_to_snowflake.py", line 6, in <module>
    from airflow.providers.snowflake.operators.snowflake import SnowflakeOperator
ModuleNotFoundError: No module named 'airflow.providers.snowflake'
[2023-03-06T12:37:59.093+0000] {processor.py:755} WARNING - No viable dags retrieved from /opt/airflow/dags/s3_to_snowflake.py
[2023-03-06T12:37:59.105+0000] {processor.py:175} INFO - Processing /opt/airflow/dags/s3_to_snowflake.py took 0.025 seconds
[2023-03-06T12:38:29.226+0000] {processor.py:153} INFO - Started process (PID=2923) to work on /opt/airflow/dags/s3_to_snowflake.py
[2023-03-06T12:38:29.227+0000] {processor.py:743} INFO - Processing file /opt/airflow/dags/s3_to_snowflake.py for tasks to queue
[2023-03-06T12:38:29.227+0000] {logging_mixin.py:137} INFO - [2023-03-06T12:38:29.227+0000] {dagbag.py:538} INFO - Filling up the DagBag from /opt/airflow/dags/s3_to_snowflake.py
[2023-03-06T12:38:29.237+0000] {logging_mixin.py:137} INFO - [2023-03-06T12:38:29.237+0000] {dagbag.py:343} ERROR - Failed to import: /opt/airflow/dags/s3_to_snowflake.py
Traceback (most recent call last):
  File "/home/airflow/.local/lib/python3.7/site-packages/airflow/models/dagbag.py", line 339, in parse
    loader.exec_module(new_module)
  File "<frozen importlib._bootstrap_external>", line 728, in exec_module
  File "<frozen importlib._bootstrap>", line 219, in _call_with_frames_removed
  File "/opt/airflow/dags/s3_to_snowflake.py", line 6, in <module>
    from airflow.providers.snowflake.operators.snowflake import SnowflakeOperator
ModuleNotFoundError: No module named 'airflow.providers.snowflake'
[2023-03-06T12:38:29.237+0000] {processor.py:755} WARNING - No viable dags retrieved from /opt/airflow/dags/s3_to_snowflake.py
[2023-03-06T12:38:29.250+0000] {processor.py:175} INFO - Processing /opt/airflow/dags/s3_to_snowflake.py took 0.025 seconds
[2023-03-06T12:38:59.377+0000] {processor.py:153} INFO - Started process (PID=2965) to work on /opt/airflow/dags/s3_to_snowflake.py
[2023-03-06T12:38:59.377+0000] {processor.py:743} INFO - Processing file /opt/airflow/dags/s3_to_snowflake.py for tasks to queue
[2023-03-06T12:38:59.377+0000] {logging_mixin.py:137} INFO - [2023-03-06T12:38:59.377+0000] {dagbag.py:538} INFO - Filling up the DagBag from /opt/airflow/dags/s3_to_snowflake.py
[2023-03-06T12:38:59.386+0000] {logging_mixin.py:137} INFO - [2023-03-06T12:38:59.386+0000] {dagbag.py:343} ERROR - Failed to import: /opt/airflow/dags/s3_to_snowflake.py
Traceback (most recent call last):
  File "/home/airflow/.local/lib/python3.7/site-packages/airflow/models/dagbag.py", line 339, in parse
    loader.exec_module(new_module)
  File "<frozen importlib._bootstrap_external>", line 728, in exec_module
  File "<frozen importlib._bootstrap>", line 219, in _call_with_frames_removed
  File "/opt/airflow/dags/s3_to_snowflake.py", line 6, in <module>
    from airflow.providers.snowflake.operators.snowflake import SnowflakeOperator
ModuleNotFoundError: No module named 'airflow.providers.snowflake'
[2023-03-06T12:38:59.387+0000] {processor.py:755} WARNING - No viable dags retrieved from /opt/airflow/dags/s3_to_snowflake.py
[2023-03-06T12:38:59.400+0000] {processor.py:175} INFO - Processing /opt/airflow/dags/s3_to_snowflake.py took 0.025 seconds
[2023-03-06T12:39:29.519+0000] {processor.py:153} INFO - Started process (PID=3027) to work on /opt/airflow/dags/s3_to_snowflake.py
[2023-03-06T12:39:29.527+0000] {processor.py:743} INFO - Processing file /opt/airflow/dags/s3_to_snowflake.py for tasks to queue
[2023-03-06T12:39:29.527+0000] {logging_mixin.py:137} INFO - [2023-03-06T12:39:29.527+0000] {dagbag.py:538} INFO - Filling up the DagBag from /opt/airflow/dags/s3_to_snowflake.py
[2023-03-06T12:39:29.538+0000] {logging_mixin.py:137} INFO - [2023-03-06T12:39:29.537+0000] {dagbag.py:343} ERROR - Failed to import: /opt/airflow/dags/s3_to_snowflake.py
Traceback (most recent call last):
  File "/home/airflow/.local/lib/python3.7/site-packages/airflow/models/dagbag.py", line 339, in parse
    loader.exec_module(new_module)
  File "<frozen importlib._bootstrap_external>", line 728, in exec_module
  File "<frozen importlib._bootstrap>", line 219, in _call_with_frames_removed
  File "/opt/airflow/dags/s3_to_snowflake.py", line 6, in <module>
    from airflow.providers.snowflake.operators.snowflake import SnowflakeOperator
ModuleNotFoundError: No module named 'airflow.providers.snowflake'
[2023-03-06T12:39:29.538+0000] {processor.py:755} WARNING - No viable dags retrieved from /opt/airflow/dags/s3_to_snowflake.py
[2023-03-06T12:39:29.553+0000] {processor.py:175} INFO - Processing /opt/airflow/dags/s3_to_snowflake.py took 0.036 seconds
[2023-03-06T12:39:59.706+0000] {processor.py:153} INFO - Started process (PID=3069) to work on /opt/airflow/dags/s3_to_snowflake.py
[2023-03-06T12:39:59.706+0000] {processor.py:743} INFO - Processing file /opt/airflow/dags/s3_to_snowflake.py for tasks to queue
[2023-03-06T12:39:59.707+0000] {logging_mixin.py:137} INFO - [2023-03-06T12:39:59.707+0000] {dagbag.py:538} INFO - Filling up the DagBag from /opt/airflow/dags/s3_to_snowflake.py
[2023-03-06T12:39:59.717+0000] {logging_mixin.py:137} INFO - [2023-03-06T12:39:59.717+0000] {dagbag.py:343} ERROR - Failed to import: /opt/airflow/dags/s3_to_snowflake.py
Traceback (most recent call last):
  File "/home/airflow/.local/lib/python3.7/site-packages/airflow/models/dagbag.py", line 339, in parse
    loader.exec_module(new_module)
  File "<frozen importlib._bootstrap_external>", line 728, in exec_module
  File "<frozen importlib._bootstrap>", line 219, in _call_with_frames_removed
  File "/opt/airflow/dags/s3_to_snowflake.py", line 6, in <module>
    from airflow.providers.snowflake.operators.snowflake import SnowflakeOperator
ModuleNotFoundError: No module named 'airflow.providers.snowflake'
[2023-03-06T12:39:59.718+0000] {processor.py:755} WARNING - No viable dags retrieved from /opt/airflow/dags/s3_to_snowflake.py
[2023-03-06T12:39:59.730+0000] {processor.py:175} INFO - Processing /opt/airflow/dags/s3_to_snowflake.py took 0.025 seconds
[2023-03-06T12:40:29.852+0000] {processor.py:153} INFO - Started process (PID=3131) to work on /opt/airflow/dags/s3_to_snowflake.py
[2023-03-06T12:40:29.860+0000] {processor.py:743} INFO - Processing file /opt/airflow/dags/s3_to_snowflake.py for tasks to queue
[2023-03-06T12:40:29.860+0000] {logging_mixin.py:137} INFO - [2023-03-06T12:40:29.860+0000] {dagbag.py:538} INFO - Filling up the DagBag from /opt/airflow/dags/s3_to_snowflake.py
[2023-03-06T12:40:29.872+0000] {logging_mixin.py:137} INFO - [2023-03-06T12:40:29.872+0000] {dagbag.py:343} ERROR - Failed to import: /opt/airflow/dags/s3_to_snowflake.py
Traceback (most recent call last):
  File "/home/airflow/.local/lib/python3.7/site-packages/airflow/models/dagbag.py", line 339, in parse
    loader.exec_module(new_module)
  File "<frozen importlib._bootstrap_external>", line 728, in exec_module
  File "<frozen importlib._bootstrap>", line 219, in _call_with_frames_removed
  File "/opt/airflow/dags/s3_to_snowflake.py", line 6, in <module>
    from airflow.providers.snowflake.operators.snowflake import SnowflakeOperator
ModuleNotFoundError: No module named 'airflow.providers.snowflake'
[2023-03-06T12:40:29.872+0000] {processor.py:755} WARNING - No viable dags retrieved from /opt/airflow/dags/s3_to_snowflake.py
[2023-03-06T12:40:29.885+0000] {processor.py:175} INFO - Processing /opt/airflow/dags/s3_to_snowflake.py took 0.035 seconds
[2023-03-06T12:41:00.008+0000] {processor.py:153} INFO - Started process (PID=3174) to work on /opt/airflow/dags/s3_to_snowflake.py
[2023-03-06T12:41:00.009+0000] {processor.py:743} INFO - Processing file /opt/airflow/dags/s3_to_snowflake.py for tasks to queue
[2023-03-06T12:41:00.009+0000] {logging_mixin.py:137} INFO - [2023-03-06T12:41:00.009+0000] {dagbag.py:538} INFO - Filling up the DagBag from /opt/airflow/dags/s3_to_snowflake.py
[2023-03-06T12:41:00.019+0000] {logging_mixin.py:137} INFO - [2023-03-06T12:41:00.019+0000] {dagbag.py:343} ERROR - Failed to import: /opt/airflow/dags/s3_to_snowflake.py
Traceback (most recent call last):
  File "/home/airflow/.local/lib/python3.7/site-packages/airflow/models/dagbag.py", line 339, in parse
    loader.exec_module(new_module)
  File "<frozen importlib._bootstrap_external>", line 728, in exec_module
  File "<frozen importlib._bootstrap>", line 219, in _call_with_frames_removed
  File "/opt/airflow/dags/s3_to_snowflake.py", line 6, in <module>
    from airflow.providers.snowflake.operators.snowflake import SnowflakeOperator
ModuleNotFoundError: No module named 'airflow.providers.snowflake'
[2023-03-06T12:41:00.020+0000] {processor.py:755} WARNING - No viable dags retrieved from /opt/airflow/dags/s3_to_snowflake.py
[2023-03-06T12:41:00.036+0000] {processor.py:175} INFO - Processing /opt/airflow/dags/s3_to_snowflake.py took 0.030 seconds
[2023-03-06T12:41:30.170+0000] {processor.py:153} INFO - Started process (PID=3236) to work on /opt/airflow/dags/s3_to_snowflake.py
[2023-03-06T12:41:30.171+0000] {processor.py:743} INFO - Processing file /opt/airflow/dags/s3_to_snowflake.py for tasks to queue
[2023-03-06T12:41:30.171+0000] {logging_mixin.py:137} INFO - [2023-03-06T12:41:30.171+0000] {dagbag.py:538} INFO - Filling up the DagBag from /opt/airflow/dags/s3_to_snowflake.py
[2023-03-06T12:41:30.182+0000] {logging_mixin.py:137} INFO - [2023-03-06T12:41:30.182+0000] {dagbag.py:343} ERROR - Failed to import: /opt/airflow/dags/s3_to_snowflake.py
Traceback (most recent call last):
  File "/home/airflow/.local/lib/python3.7/site-packages/airflow/models/dagbag.py", line 339, in parse
    loader.exec_module(new_module)
  File "<frozen importlib._bootstrap_external>", line 728, in exec_module
  File "<frozen importlib._bootstrap>", line 219, in _call_with_frames_removed
  File "/opt/airflow/dags/s3_to_snowflake.py", line 6, in <module>
    from airflow.providers.snowflake.operators.snowflake import SnowflakeOperator
ModuleNotFoundError: No module named 'airflow.providers.snowflake'
[2023-03-06T12:41:30.183+0000] {processor.py:755} WARNING - No viable dags retrieved from /opt/airflow/dags/s3_to_snowflake.py
[2023-03-06T12:41:30.197+0000] {processor.py:175} INFO - Processing /opt/airflow/dags/s3_to_snowflake.py took 0.029 seconds
[2023-03-06T12:42:00.319+0000] {processor.py:153} INFO - Started process (PID=3287) to work on /opt/airflow/dags/s3_to_snowflake.py
[2023-03-06T12:42:00.319+0000] {processor.py:743} INFO - Processing file /opt/airflow/dags/s3_to_snowflake.py for tasks to queue
[2023-03-06T12:42:00.319+0000] {logging_mixin.py:137} INFO - [2023-03-06T12:42:00.319+0000] {dagbag.py:538} INFO - Filling up the DagBag from /opt/airflow/dags/s3_to_snowflake.py
[2023-03-06T12:42:00.329+0000] {logging_mixin.py:137} INFO - [2023-03-06T12:42:00.328+0000] {dagbag.py:343} ERROR - Failed to import: /opt/airflow/dags/s3_to_snowflake.py
Traceback (most recent call last):
  File "/home/airflow/.local/lib/python3.7/site-packages/airflow/models/dagbag.py", line 339, in parse
    loader.exec_module(new_module)
  File "<frozen importlib._bootstrap_external>", line 728, in exec_module
  File "<frozen importlib._bootstrap>", line 219, in _call_with_frames_removed
  File "/opt/airflow/dags/s3_to_snowflake.py", line 6, in <module>
    from airflow.providers.snowflake.operators.snowflake import SnowflakeOperator
ModuleNotFoundError: No module named 'airflow.providers.snowflake'
[2023-03-06T12:42:00.329+0000] {processor.py:755} WARNING - No viable dags retrieved from /opt/airflow/dags/s3_to_snowflake.py
[2023-03-06T12:42:00.342+0000] {processor.py:175} INFO - Processing /opt/airflow/dags/s3_to_snowflake.py took 0.025 seconds
[2023-03-06T12:42:30.461+0000] {processor.py:153} INFO - Started process (PID=3340) to work on /opt/airflow/dags/s3_to_snowflake.py
[2023-03-06T12:42:30.462+0000] {processor.py:743} INFO - Processing file /opt/airflow/dags/s3_to_snowflake.py for tasks to queue
[2023-03-06T12:42:30.462+0000] {logging_mixin.py:137} INFO - [2023-03-06T12:42:30.462+0000] {dagbag.py:538} INFO - Filling up the DagBag from /opt/airflow/dags/s3_to_snowflake.py
[2023-03-06T12:42:30.473+0000] {logging_mixin.py:137} INFO - [2023-03-06T12:42:30.472+0000] {dagbag.py:343} ERROR - Failed to import: /opt/airflow/dags/s3_to_snowflake.py
Traceback (most recent call last):
  File "/home/airflow/.local/lib/python3.7/site-packages/airflow/models/dagbag.py", line 339, in parse
    loader.exec_module(new_module)
  File "<frozen importlib._bootstrap_external>", line 728, in exec_module
  File "<frozen importlib._bootstrap>", line 219, in _call_with_frames_removed
  File "/opt/airflow/dags/s3_to_snowflake.py", line 6, in <module>
    from airflow.providers.snowflake.operators.snowflake import SnowflakeOperator
ModuleNotFoundError: No module named 'airflow.providers.snowflake'
[2023-03-06T12:42:30.473+0000] {processor.py:755} WARNING - No viable dags retrieved from /opt/airflow/dags/s3_to_snowflake.py
[2023-03-06T12:42:30.486+0000] {processor.py:175} INFO - Processing /opt/airflow/dags/s3_to_snowflake.py took 0.026 seconds
[2023-03-06T12:43:00.602+0000] {processor.py:153} INFO - Started process (PID=3402) to work on /opt/airflow/dags/s3_to_snowflake.py
[2023-03-06T12:43:00.602+0000] {processor.py:743} INFO - Processing file /opt/airflow/dags/s3_to_snowflake.py for tasks to queue
[2023-03-06T12:43:00.603+0000] {logging_mixin.py:137} INFO - [2023-03-06T12:43:00.603+0000] {dagbag.py:538} INFO - Filling up the DagBag from /opt/airflow/dags/s3_to_snowflake.py
[2023-03-06T12:43:00.614+0000] {logging_mixin.py:137} INFO - [2023-03-06T12:43:00.614+0000] {dagbag.py:343} ERROR - Failed to import: /opt/airflow/dags/s3_to_snowflake.py
Traceback (most recent call last):
  File "/home/airflow/.local/lib/python3.7/site-packages/airflow/models/dagbag.py", line 339, in parse
    loader.exec_module(new_module)
  File "<frozen importlib._bootstrap_external>", line 728, in exec_module
  File "<frozen importlib._bootstrap>", line 219, in _call_with_frames_removed
  File "/opt/airflow/dags/s3_to_snowflake.py", line 6, in <module>
    from airflow.providers.snowflake.operators.snowflake import SnowflakeOperator
ModuleNotFoundError: No module named 'airflow.providers.snowflake'
[2023-03-06T12:43:00.614+0000] {processor.py:755} WARNING - No viable dags retrieved from /opt/airflow/dags/s3_to_snowflake.py
[2023-03-06T12:43:00.627+0000] {processor.py:175} INFO - Processing /opt/airflow/dags/s3_to_snowflake.py took 0.027 seconds
[2023-03-06T12:43:30.744+0000] {processor.py:153} INFO - Started process (PID=3444) to work on /opt/airflow/dags/s3_to_snowflake.py
[2023-03-06T12:43:30.744+0000] {processor.py:743} INFO - Processing file /opt/airflow/dags/s3_to_snowflake.py for tasks to queue
[2023-03-06T12:43:30.745+0000] {logging_mixin.py:137} INFO - [2023-03-06T12:43:30.745+0000] {dagbag.py:538} INFO - Filling up the DagBag from /opt/airflow/dags/s3_to_snowflake.py
[2023-03-06T12:43:30.757+0000] {logging_mixin.py:137} INFO - [2023-03-06T12:43:30.756+0000] {dagbag.py:343} ERROR - Failed to import: /opt/airflow/dags/s3_to_snowflake.py
Traceback (most recent call last):
  File "/home/airflow/.local/lib/python3.7/site-packages/airflow/models/dagbag.py", line 339, in parse
    loader.exec_module(new_module)
  File "<frozen importlib._bootstrap_external>", line 728, in exec_module
  File "<frozen importlib._bootstrap>", line 219, in _call_with_frames_removed
  File "/opt/airflow/dags/s3_to_snowflake.py", line 6, in <module>
    from airflow.providers.snowflake.operators.snowflake import SnowflakeOperator
ModuleNotFoundError: No module named 'airflow.providers.snowflake'
[2023-03-06T12:43:30.757+0000] {processor.py:755} WARNING - No viable dags retrieved from /opt/airflow/dags/s3_to_snowflake.py
[2023-03-06T12:43:30.769+0000] {processor.py:175} INFO - Processing /opt/airflow/dags/s3_to_snowflake.py took 0.027 seconds
[2023-03-06T12:44:00.885+0000] {processor.py:153} INFO - Started process (PID=3506) to work on /opt/airflow/dags/s3_to_snowflake.py
[2023-03-06T12:44:00.885+0000] {processor.py:743} INFO - Processing file /opt/airflow/dags/s3_to_snowflake.py for tasks to queue
[2023-03-06T12:44:00.886+0000] {logging_mixin.py:137} INFO - [2023-03-06T12:44:00.886+0000] {dagbag.py:538} INFO - Filling up the DagBag from /opt/airflow/dags/s3_to_snowflake.py
[2023-03-06T12:44:00.906+0000] {logging_mixin.py:137} INFO - [2023-03-06T12:44:00.903+0000] {dagbag.py:343} ERROR - Failed to import: /opt/airflow/dags/s3_to_snowflake.py
Traceback (most recent call last):
  File "/home/airflow/.local/lib/python3.7/site-packages/airflow/models/dagbag.py", line 339, in parse
    loader.exec_module(new_module)
  File "<frozen importlib._bootstrap_external>", line 728, in exec_module
  File "<frozen importlib._bootstrap>", line 219, in _call_with_frames_removed
  File "/opt/airflow/dags/s3_to_snowflake.py", line 6, in <module>
    from airflow.providers.snowflake.operators.snowflake import SnowflakeOperator
ModuleNotFoundError: No module named 'airflow.providers.snowflake'
[2023-03-06T12:44:00.906+0000] {processor.py:755} WARNING - No viable dags retrieved from /opt/airflow/dags/s3_to_snowflake.py
[2023-03-06T12:44:00.924+0000] {processor.py:175} INFO - Processing /opt/airflow/dags/s3_to_snowflake.py took 0.041 seconds
[2023-03-06T23:54:57.754+0000] {processor.py:153} INFO - Started process (PID=42) to work on /opt/airflow/dags/s3_to_snowflake.py
[2023-03-06T23:54:57.755+0000] {processor.py:743} INFO - Processing file /opt/airflow/dags/s3_to_snowflake.py for tasks to queue
[2023-03-06T23:54:57.756+0000] {logging_mixin.py:137} INFO - [2023-03-06T23:54:57.756+0000] {dagbag.py:538} INFO - Filling up the DagBag from /opt/airflow/dags/s3_to_snowflake.py
[2023-03-06T23:54:57.831+0000] {logging_mixin.py:137} INFO - [2023-03-06T23:54:57.828+0000] {dagbag.py:343} ERROR - Failed to import: /opt/airflow/dags/s3_to_snowflake.py
Traceback (most recent call last):
  File "/home/airflow/.local/lib/python3.7/site-packages/airflow/models/dagbag.py", line 339, in parse
    loader.exec_module(new_module)
  File "<frozen importlib._bootstrap_external>", line 728, in exec_module
  File "<frozen importlib._bootstrap>", line 219, in _call_with_frames_removed
  File "/opt/airflow/dags/s3_to_snowflake.py", line 6, in <module>
    from airflow.providers.snowflake.operators.snowflake import SnowflakeOperator
ModuleNotFoundError: No module named 'airflow.providers.snowflake'
[2023-03-06T23:54:57.831+0000] {processor.py:755} WARNING - No viable dags retrieved from /opt/airflow/dags/s3_to_snowflake.py
[2023-03-06T23:54:57.870+0000] {processor.py:175} INFO - Processing /opt/airflow/dags/s3_to_snowflake.py took 0.126 seconds
[2023-03-06T23:55:27.980+0000] {processor.py:153} INFO - Started process (PID=104) to work on /opt/airflow/dags/s3_to_snowflake.py
[2023-03-06T23:55:27.981+0000] {processor.py:743} INFO - Processing file /opt/airflow/dags/s3_to_snowflake.py for tasks to queue
[2023-03-06T23:55:27.981+0000] {logging_mixin.py:137} INFO - [2023-03-06T23:55:27.981+0000] {dagbag.py:538} INFO - Filling up the DagBag from /opt/airflow/dags/s3_to_snowflake.py
[2023-03-06T23:55:27.991+0000] {logging_mixin.py:137} INFO - [2023-03-06T23:55:27.991+0000] {dagbag.py:343} ERROR - Failed to import: /opt/airflow/dags/s3_to_snowflake.py
Traceback (most recent call last):
  File "/home/airflow/.local/lib/python3.7/site-packages/airflow/models/dagbag.py", line 339, in parse
    loader.exec_module(new_module)
  File "<frozen importlib._bootstrap_external>", line 728, in exec_module
  File "<frozen importlib._bootstrap>", line 219, in _call_with_frames_removed
  File "/opt/airflow/dags/s3_to_snowflake.py", line 6, in <module>
    from airflow.providers.snowflake.operators.snowflake import SnowflakeOperator
ModuleNotFoundError: No module named 'airflow.providers.snowflake'
[2023-03-06T23:55:27.991+0000] {processor.py:755} WARNING - No viable dags retrieved from /opt/airflow/dags/s3_to_snowflake.py
[2023-03-06T23:55:28.003+0000] {processor.py:175} INFO - Processing /opt/airflow/dags/s3_to_snowflake.py took 0.025 seconds
[2023-03-06T23:57:25.896+0000] {processor.py:153} INFO - Started process (PID=42) to work on /opt/airflow/dags/s3_to_snowflake.py
[2023-03-06T23:57:25.896+0000] {processor.py:743} INFO - Processing file /opt/airflow/dags/s3_to_snowflake.py for tasks to queue
[2023-03-06T23:57:25.897+0000] {logging_mixin.py:137} INFO - [2023-03-06T23:57:25.897+0000] {dagbag.py:538} INFO - Filling up the DagBag from /opt/airflow/dags/s3_to_snowflake.py
[2023-03-06T23:57:26.412+0000] {logging_mixin.py:137} WARNING - /home/airflow/.local/lib/python3.7/site-packages/snowflake/connector/options.py:108 UserWarning: You have an incompatible version of 'pyarrow' installed (9.0.0), please install a version that adheres to: 'pyarrow<10.1.0,>=10.0.1; extra == "pandas"'
[2023-03-06T23:57:26.675+0000] {logging_mixin.py:137} INFO - [2023-03-06T23:57:26.674+0000] {dagbag.py:343} ERROR - Failed to import: /opt/airflow/dags/s3_to_snowflake.py
Traceback (most recent call last):
  File "/home/airflow/.local/lib/python3.7/site-packages/airflow/models/dagbag.py", line 339, in parse
    loader.exec_module(new_module)
  File "<frozen importlib._bootstrap_external>", line 728, in exec_module
  File "<frozen importlib._bootstrap>", line 219, in _call_with_frames_removed
  File "/opt/airflow/dags/s3_to_snowflake.py", line 154, in <module>
    copy_into_results_table] >> drop_warehouse
TypeError: unsupported operand type(s) for >>: 'list' and 'list'
[2023-03-06T23:57:26.675+0000] {processor.py:755} WARNING - No viable dags retrieved from /opt/airflow/dags/s3_to_snowflake.py
[2023-03-06T23:57:26.686+0000] {processor.py:175} INFO - Processing /opt/airflow/dags/s3_to_snowflake.py took 0.795 seconds
[2023-03-06T23:57:57.462+0000] {processor.py:153} INFO - Started process (PID=107) to work on /opt/airflow/dags/s3_to_snowflake.py
[2023-03-06T23:57:57.462+0000] {processor.py:743} INFO - Processing file /opt/airflow/dags/s3_to_snowflake.py for tasks to queue
[2023-03-06T23:57:57.463+0000] {logging_mixin.py:137} INFO - [2023-03-06T23:57:57.463+0000] {dagbag.py:538} INFO - Filling up the DagBag from /opt/airflow/dags/s3_to_snowflake.py
[2023-03-06T23:57:57.902+0000] {logging_mixin.py:137} WARNING - /home/airflow/.local/lib/python3.7/site-packages/snowflake/connector/options.py:108 UserWarning: You have an incompatible version of 'pyarrow' installed (9.0.0), please install a version that adheres to: 'pyarrow<10.1.0,>=10.0.1; extra == "pandas"'
[2023-03-06T23:57:58.046+0000] {logging_mixin.py:137} INFO - [2023-03-06T23:57:58.046+0000] {dagbag.py:343} ERROR - Failed to import: /opt/airflow/dags/s3_to_snowflake.py
Traceback (most recent call last):
  File "/home/airflow/.local/lib/python3.7/site-packages/airflow/models/dagbag.py", line 339, in parse
    loader.exec_module(new_module)
  File "<frozen importlib._bootstrap_external>", line 728, in exec_module
  File "<frozen importlib._bootstrap>", line 219, in _call_with_frames_removed
  File "/opt/airflow/dags/s3_to_snowflake.py", line 154, in <module>
    copy_into_results_table] >> drop_warehouse
TypeError: unsupported operand type(s) for >>: 'list' and 'list'
[2023-03-06T23:57:58.047+0000] {processor.py:755} WARNING - No viable dags retrieved from /opt/airflow/dags/s3_to_snowflake.py
[2023-03-06T23:57:58.059+0000] {processor.py:175} INFO - Processing /opt/airflow/dags/s3_to_snowflake.py took 0.598 seconds
[2023-03-06T23:58:28.669+0000] {processor.py:153} INFO - Started process (PID=160) to work on /opt/airflow/dags/s3_to_snowflake.py
[2023-03-06T23:58:28.669+0000] {processor.py:743} INFO - Processing file /opt/airflow/dags/s3_to_snowflake.py for tasks to queue
[2023-03-06T23:58:28.669+0000] {logging_mixin.py:137} INFO - [2023-03-06T23:58:28.669+0000] {dagbag.py:538} INFO - Filling up the DagBag from /opt/airflow/dags/s3_to_snowflake.py
[2023-03-06T23:58:29.171+0000] {logging_mixin.py:137} WARNING - /home/airflow/.local/lib/python3.7/site-packages/snowflake/connector/options.py:108 UserWarning: You have an incompatible version of 'pyarrow' installed (9.0.0), please install a version that adheres to: 'pyarrow<10.1.0,>=10.0.1; extra == "pandas"'
[2023-03-06T23:58:29.310+0000] {logging_mixin.py:137} INFO - [2023-03-06T23:58:29.309+0000] {dagbag.py:343} ERROR - Failed to import: /opt/airflow/dags/s3_to_snowflake.py
Traceback (most recent call last):
  File "/home/airflow/.local/lib/python3.7/site-packages/airflow/models/dagbag.py", line 339, in parse
    loader.exec_module(new_module)
  File "<frozen importlib._bootstrap_external>", line 728, in exec_module
  File "<frozen importlib._bootstrap>", line 219, in _call_with_frames_removed
  File "/opt/airflow/dags/s3_to_snowflake.py", line 154, in <module>
    copy_into_results_table] >> drop_warehouse
TypeError: unsupported operand type(s) for >>: 'list' and 'list'
[2023-03-06T23:58:29.310+0000] {processor.py:755} WARNING - No viable dags retrieved from /opt/airflow/dags/s3_to_snowflake.py
[2023-03-06T23:58:29.322+0000] {processor.py:175} INFO - Processing /opt/airflow/dags/s3_to_snowflake.py took 0.655 seconds
[2023-03-06T23:58:59.919+0000] {processor.py:153} INFO - Started process (PID=214) to work on /opt/airflow/dags/s3_to_snowflake.py
[2023-03-06T23:58:59.921+0000] {processor.py:743} INFO - Processing file /opt/airflow/dags/s3_to_snowflake.py for tasks to queue
[2023-03-06T23:58:59.921+0000] {logging_mixin.py:137} INFO - [2023-03-06T23:58:59.921+0000] {dagbag.py:538} INFO - Filling up the DagBag from /opt/airflow/dags/s3_to_snowflake.py
[2023-03-06T23:59:00.335+0000] {logging_mixin.py:137} WARNING - /home/airflow/.local/lib/python3.7/site-packages/snowflake/connector/options.py:108 UserWarning: You have an incompatible version of 'pyarrow' installed (9.0.0), please install a version that adheres to: 'pyarrow<10.1.0,>=10.0.1; extra == "pandas"'
[2023-03-06T23:59:00.474+0000] {logging_mixin.py:137} INFO - [2023-03-06T23:59:00.474+0000] {dagbag.py:343} ERROR - Failed to import: /opt/airflow/dags/s3_to_snowflake.py
Traceback (most recent call last):
  File "/home/airflow/.local/lib/python3.7/site-packages/airflow/models/dagbag.py", line 339, in parse
    loader.exec_module(new_module)
  File "<frozen importlib._bootstrap_external>", line 728, in exec_module
  File "<frozen importlib._bootstrap>", line 219, in _call_with_frames_removed
  File "/opt/airflow/dags/s3_to_snowflake.py", line 154, in <module>
    copy_into_results_table] >> drop_warehouse
TypeError: unsupported operand type(s) for >>: 'list' and 'list'
[2023-03-06T23:59:00.475+0000] {processor.py:755} WARNING - No viable dags retrieved from /opt/airflow/dags/s3_to_snowflake.py
[2023-03-06T23:59:00.486+0000] {processor.py:175} INFO - Processing /opt/airflow/dags/s3_to_snowflake.py took 0.569 seconds
[2023-03-06T23:59:31.178+0000] {processor.py:153} INFO - Started process (PID=278) to work on /opt/airflow/dags/s3_to_snowflake.py
[2023-03-06T23:59:31.178+0000] {processor.py:743} INFO - Processing file /opt/airflow/dags/s3_to_snowflake.py for tasks to queue
[2023-03-06T23:59:31.178+0000] {logging_mixin.py:137} INFO - [2023-03-06T23:59:31.178+0000] {dagbag.py:538} INFO - Filling up the DagBag from /opt/airflow/dags/s3_to_snowflake.py
[2023-03-06T23:59:31.597+0000] {logging_mixin.py:137} WARNING - /home/airflow/.local/lib/python3.7/site-packages/snowflake/connector/options.py:108 UserWarning: You have an incompatible version of 'pyarrow' installed (9.0.0), please install a version that adheres to: 'pyarrow<10.1.0,>=10.0.1; extra == "pandas"'
[2023-03-06T23:59:31.732+0000] {logging_mixin.py:137} INFO - [2023-03-06T23:59:31.731+0000] {dagbag.py:343} ERROR - Failed to import: /opt/airflow/dags/s3_to_snowflake.py
Traceback (most recent call last):
  File "/home/airflow/.local/lib/python3.7/site-packages/airflow/models/dagbag.py", line 339, in parse
    loader.exec_module(new_module)
  File "<frozen importlib._bootstrap_external>", line 728, in exec_module
  File "<frozen importlib._bootstrap>", line 219, in _call_with_frames_removed
  File "/opt/airflow/dags/s3_to_snowflake.py", line 154, in <module>
    copy_into_races_table, copy_into_constructors_table,
TypeError: unsupported operand type(s) for >>: 'list' and 'list'
[2023-03-06T23:59:31.732+0000] {processor.py:755} WARNING - No viable dags retrieved from /opt/airflow/dags/s3_to_snowflake.py
[2023-03-06T23:59:31.743+0000] {processor.py:175} INFO - Processing /opt/airflow/dags/s3_to_snowflake.py took 0.568 seconds
[2023-03-06T23:59:33.402+0000] {processor.py:153} INFO - Started process (PID=281) to work on /opt/airflow/dags/s3_to_snowflake.py
[2023-03-06T23:59:33.403+0000] {processor.py:743} INFO - Processing file /opt/airflow/dags/s3_to_snowflake.py for tasks to queue
[2023-03-06T23:59:33.403+0000] {logging_mixin.py:137} INFO - [2023-03-06T23:59:33.403+0000] {dagbag.py:538} INFO - Filling up the DagBag from /opt/airflow/dags/s3_to_snowflake.py
[2023-03-06T23:59:33.792+0000] {logging_mixin.py:137} WARNING - /home/airflow/.local/lib/python3.7/site-packages/snowflake/connector/options.py:108 UserWarning: You have an incompatible version of 'pyarrow' installed (9.0.0), please install a version that adheres to: 'pyarrow<10.1.0,>=10.0.1; extra == "pandas"'
[2023-03-06T23:59:33.923+0000] {logging_mixin.py:137} INFO - [2023-03-06T23:59:33.923+0000] {dagbag.py:343} ERROR - Failed to import: /opt/airflow/dags/s3_to_snowflake.py
Traceback (most recent call last):
  File "/home/airflow/.local/lib/python3.7/site-packages/airflow/models/dagbag.py", line 339, in parse
    loader.exec_module(new_module)
  File "<frozen importlib._bootstrap_external>", line 728, in exec_module
  File "<frozen importlib._bootstrap>", line 219, in _call_with_frames_removed
  File "/opt/airflow/dags/s3_to_snowflake.py", line 154, in <module>
    copy_into_results_table] >> drop_warehouse
TypeError: unsupported operand type(s) for >>: 'list' and 'list'
[2023-03-06T23:59:33.924+0000] {processor.py:755} WARNING - No viable dags retrieved from /opt/airflow/dags/s3_to_snowflake.py
[2023-03-06T23:59:33.936+0000] {processor.py:175} INFO - Processing /opt/airflow/dags/s3_to_snowflake.py took 0.535 seconds
[2023-03-06T23:59:34.771+0000] {processor.py:153} INFO - Started process (PID=284) to work on /opt/airflow/dags/s3_to_snowflake.py
[2023-03-06T23:59:34.771+0000] {processor.py:743} INFO - Processing file /opt/airflow/dags/s3_to_snowflake.py for tasks to queue
[2023-03-06T23:59:34.771+0000] {logging_mixin.py:137} INFO - [2023-03-06T23:59:34.771+0000] {dagbag.py:538} INFO - Filling up the DagBag from /opt/airflow/dags/s3_to_snowflake.py
[2023-03-06T23:59:35.156+0000] {logging_mixin.py:137} WARNING - /home/airflow/.local/lib/python3.7/site-packages/snowflake/connector/options.py:108 UserWarning: You have an incompatible version of 'pyarrow' installed (9.0.0), please install a version that adheres to: 'pyarrow<10.1.0,>=10.0.1; extra == "pandas"'
[2023-03-06T23:59:35.287+0000] {logging_mixin.py:137} INFO - [2023-03-06T23:59:35.286+0000] {dagbag.py:343} ERROR - Failed to import: /opt/airflow/dags/s3_to_snowflake.py
Traceback (most recent call last):
  File "/home/airflow/.local/lib/python3.7/site-packages/airflow/models/dagbag.py", line 339, in parse
    loader.exec_module(new_module)
  File "<frozen importlib._bootstrap_external>", line 728, in exec_module
  File "<frozen importlib._bootstrap>", line 219, in _call_with_frames_removed
  File "/opt/airflow/dags/s3_to_snowflake.py", line 154, in <module>
    copy_into_results_table] >> drop_warehouse
TypeError: unsupported operand type(s) for >>: 'list' and 'list'
[2023-03-06T23:59:35.287+0000] {processor.py:755} WARNING - No viable dags retrieved from /opt/airflow/dags/s3_to_snowflake.py
[2023-03-06T23:59:35.298+0000] {processor.py:175} INFO - Processing /opt/airflow/dags/s3_to_snowflake.py took 0.529 seconds
[2023-03-06T23:59:50.006+0000] {processor.py:153} INFO - Started process (PID=307) to work on /opt/airflow/dags/s3_to_snowflake.py
[2023-03-06T23:59:50.007+0000] {processor.py:743} INFO - Processing file /opt/airflow/dags/s3_to_snowflake.py for tasks to queue
[2023-03-06T23:59:50.007+0000] {logging_mixin.py:137} INFO - [2023-03-06T23:59:50.007+0000] {dagbag.py:538} INFO - Filling up the DagBag from /opt/airflow/dags/s3_to_snowflake.py
[2023-03-06T23:59:50.394+0000] {logging_mixin.py:137} WARNING - /home/airflow/.local/lib/python3.7/site-packages/snowflake/connector/options.py:108 UserWarning: You have an incompatible version of 'pyarrow' installed (9.0.0), please install a version that adheres to: 'pyarrow<10.1.0,>=10.0.1; extra == "pandas"'
[2023-03-06T23:59:50.534+0000] {logging_mixin.py:137} INFO - [2023-03-06T23:59:50.533+0000] {dagbag.py:343} ERROR - Failed to import: /opt/airflow/dags/s3_to_snowflake.py
Traceback (most recent call last):
  File "/home/airflow/.local/lib/python3.7/site-packages/airflow/models/dagbag.py", line 339, in parse
    loader.exec_module(new_module)
  File "<frozen importlib._bootstrap_external>", line 728, in exec_module
  File "<frozen importlib._bootstrap>", line 219, in _call_with_frames_removed
  File "/opt/airflow/dags/s3_to_snowflake.py", line 153, in <module>
    copy_into_results_table] >> drop_warehouse
TypeError: unsupported operand type(s) for >>: 'list' and 'list'
[2023-03-06T23:59:50.534+0000] {processor.py:755} WARNING - No viable dags retrieved from /opt/airflow/dags/s3_to_snowflake.py
[2023-03-06T23:59:50.546+0000] {processor.py:175} INFO - Processing /opt/airflow/dags/s3_to_snowflake.py took 0.542 seconds
[2023-03-06T23:59:55.381+0000] {processor.py:153} INFO - Started process (PID=330) to work on /opt/airflow/dags/s3_to_snowflake.py
[2023-03-06T23:59:55.381+0000] {processor.py:743} INFO - Processing file /opt/airflow/dags/s3_to_snowflake.py for tasks to queue
[2023-03-06T23:59:55.382+0000] {logging_mixin.py:137} INFO - [2023-03-06T23:59:55.382+0000] {dagbag.py:538} INFO - Filling up the DagBag from /opt/airflow/dags/s3_to_snowflake.py
[2023-03-06T23:59:55.776+0000] {logging_mixin.py:137} WARNING - /home/airflow/.local/lib/python3.7/site-packages/snowflake/connector/options.py:108 UserWarning: You have an incompatible version of 'pyarrow' installed (9.0.0), please install a version that adheres to: 'pyarrow<10.1.0,>=10.0.1; extra == "pandas"'
[2023-03-06T23:59:55.920+0000] {logging_mixin.py:137} INFO - [2023-03-06T23:59:55.919+0000] {dagbag.py:343} ERROR - Failed to import: /opt/airflow/dags/s3_to_snowflake.py
Traceback (most recent call last):
  File "/home/airflow/.local/lib/python3.7/site-packages/airflow/models/dagbag.py", line 339, in parse
    loader.exec_module(new_module)
  File "<frozen importlib._bootstrap_external>", line 728, in exec_module
  File "<frozen importlib._bootstrap>", line 219, in _call_with_frames_removed
  File "/opt/airflow/dags/s3_to_snowflake.py", line 152, in <module>
    create_constructors_table, create_races_table] >> [copy_into_circuits_table, copy_into_races_table, copy_into_constructors_table, copy_into_results_table] >> drop_warehouse
TypeError: unsupported operand type(s) for >>: 'list' and 'list'
[2023-03-06T23:59:55.920+0000] {processor.py:755} WARNING - No viable dags retrieved from /opt/airflow/dags/s3_to_snowflake.py
[2023-03-06T23:59:55.935+0000] {processor.py:175} INFO - Processing /opt/airflow/dags/s3_to_snowflake.py took 0.555 seconds
