[2023-03-05T20:10:40.151+0000] {taskinstance.py:1083} INFO - Dependencies all met for <TaskInstance: formula1_upload_to_s3.circuits_upload manual__2023-03-05T20:10:38.818733+00:00 [queued]>
[2023-03-05T20:10:40.158+0000] {taskinstance.py:1083} INFO - Dependencies all met for <TaskInstance: formula1_upload_to_s3.circuits_upload manual__2023-03-05T20:10:38.818733+00:00 [queued]>
[2023-03-05T20:10:40.159+0000] {taskinstance.py:1279} INFO - 
--------------------------------------------------------------------------------
[2023-03-05T20:10:40.159+0000] {taskinstance.py:1280} INFO - Starting attempt 1 of 6
[2023-03-05T20:10:40.159+0000] {taskinstance.py:1281} INFO - 
--------------------------------------------------------------------------------
[2023-03-05T20:10:40.170+0000] {taskinstance.py:1300} INFO - Executing <Task(PythonOperator): circuits_upload> on 2023-03-05 20:10:38.818733+00:00
[2023-03-05T20:10:40.174+0000] {standard_task_runner.py:55} INFO - Started process 10909 to run task
[2023-03-05T20:10:40.176+0000] {standard_task_runner.py:82} INFO - Running: ['***', 'tasks', 'run', 'formula1_upload_to_s3', 'circuits_upload', 'manual__2023-03-05T20:10:38.818733+00:00', '--job-id', '13', '--raw', '--subdir', 'DAGS_FOLDER/s3_upload_dag.py', '--cfg-path', '/tmp/tmpt7f2s7tt']
[2023-03-05T20:10:40.176+0000] {standard_task_runner.py:83} INFO - Job 13: Subtask circuits_upload
[2023-03-05T20:10:40.225+0000] {task_command.py:388} INFO - Running <TaskInstance: formula1_upload_to_s3.circuits_upload manual__2023-03-05T20:10:38.818733+00:00 [running]> on host a4cedc34403c
[2023-03-05T20:10:40.300+0000] {taskinstance.py:1509} INFO - Exporting the following env vars:
AIRFLOW_CTX_DAG_OWNER=tem109
AIRFLOW_CTX_DAG_ID=formula1_upload_to_s3
AIRFLOW_CTX_TASK_ID=circuits_upload
AIRFLOW_CTX_EXECUTION_DATE=2023-03-05T20:10:38.818733+00:00
AIRFLOW_CTX_TRY_NUMBER=1
AIRFLOW_CTX_DAG_RUN_ID=manual__2023-03-05T20:10:38.818733+00:00
[2023-03-05T20:10:40.309+0000] {base.py:73} INFO - Using connection ID 'postgres_localhost' for task execution.
[2023-03-05T20:10:40.324+0000] {s3_upload_dag.py:33} INFO - Saved circuits data
[2023-03-05T20:10:40.336+0000] {base.py:73} INFO - Using connection ID 's3_conn' for task execution.
[2023-03-05T20:10:40.337+0000] {connection_wrapper.py:334} INFO - AWS Connection (conn_id='s3_conn', conn_type='aws') credentials retrieved from login and password.
[2023-03-05T20:10:41.607+0000] {taskinstance.py:1768} ERROR - Task failed with exception
Traceback (most recent call last):
  File "/home/airflow/.local/lib/python3.7/site-packages/boto3/s3/transfer.py", line 292, in upload_file
    future.result()
  File "/home/airflow/.local/lib/python3.7/site-packages/s3transfer/futures.py", line 103, in result
    return self._coordinator.result()
  File "/home/airflow/.local/lib/python3.7/site-packages/s3transfer/futures.py", line 266, in result
    raise self._exception
  File "/home/airflow/.local/lib/python3.7/site-packages/s3transfer/tasks.py", line 139, in __call__
    return self._execute_main(kwargs)
  File "/home/airflow/.local/lib/python3.7/site-packages/s3transfer/tasks.py", line 162, in _execute_main
    return_value = self._main(**kwargs)
  File "/home/airflow/.local/lib/python3.7/site-packages/s3transfer/upload.py", line 758, in _main
    client.put_object(Bucket=bucket, Key=key, Body=body, **extra_args)
  File "/home/airflow/.local/lib/python3.7/site-packages/botocore/client.py", line 530, in _api_call
    return self._make_api_call(operation_name, kwargs)
  File "/home/airflow/.local/lib/python3.7/site-packages/botocore/client.py", line 960, in _make_api_call
    raise error_class(parsed_response, operation_name)
botocore.exceptions.ClientError: An error occurred (AccessDenied) when calling the PutObject operation: Access Denied

During handling of the above exception, another exception occurred:

Traceback (most recent call last):
  File "/home/airflow/.local/lib/python3.7/site-packages/airflow/operators/python.py", line 175, in execute
    return_value = self.execute_callable()
  File "/home/airflow/.local/lib/python3.7/site-packages/airflow/operators/python.py", line 192, in execute_callable
    return self.python_callable(*self.op_args, **self.op_kwargs)
  File "/opt/airflow/dags/s3_upload_dag.py", line 40, in circuits_upload
    replace = True     ## Replace file if already exists
  File "/home/airflow/.local/lib/python3.7/site-packages/airflow/providers/amazon/aws/hooks/s3.py", line 99, in wrapper
    return func(*bound_args.args, **bound_args.kwargs)
  File "/home/airflow/.local/lib/python3.7/site-packages/airflow/providers/amazon/aws/hooks/s3.py", line 70, in wrapper
    return func(*bound_args.args, **bound_args.kwargs)
  File "/home/airflow/.local/lib/python3.7/site-packages/airflow/providers/amazon/aws/hooks/s3.py", line 646, in load_file
    client.upload_file(filename, bucket_name, key, ExtraArgs=extra_args, Config=self.transfer_config)
  File "/home/airflow/.local/lib/python3.7/site-packages/boto3/s3/inject.py", line 148, in upload_file
    callback=Callback,
  File "/home/airflow/.local/lib/python3.7/site-packages/boto3/s3/transfer.py", line 300, in upload_file
    filename, '/'.join([bucket, key]), e
boto3.exceptions.S3UploadFailedError: Failed to upload dags/get_circuits.csv to formula1/circuits.csv: An error occurred (AccessDenied) when calling the PutObject operation: Access Denied
[2023-03-05T20:10:41.615+0000] {taskinstance.py:1323} INFO - Marking task as UP_FOR_RETRY. dag_id=formula1_upload_to_s3, task_id=circuits_upload, execution_date=20230305T201038, start_date=20230305T201040, end_date=20230305T201041
[2023-03-05T20:10:41.624+0000] {standard_task_runner.py:105} ERROR - Failed to execute job 13 for task circuits_upload (Failed to upload dags/get_circuits.csv to formula1/circuits.csv: An error occurred (AccessDenied) when calling the PutObject operation: Access Denied; 10909)
[2023-03-05T20:10:41.633+0000] {local_task_job.py:208} INFO - Task exited with return code 1
[2023-03-05T20:10:41.649+0000] {taskinstance.py:2578} INFO - 0 downstream tasks scheduled from follow-on schedule check
